Workbook

Sheet Buyers
A1: # | B1: company | C1: url | D1: city | E1: sector | F1: oneline_description | G1: est._size | H1: automation_signal | I1: selfhost_compliance_driver | J1: score_breakdown | K1: score | L1: suggested_firstline_hook | M1: list | N1: contacts | O1: n_contacts | P1: owner | Q1: contact_email | R1: touch1_date | S1: followup_date | T1: breakup_date | U1: replied | V1: call_booked | W1: call_held | X1: status | Y1: notes
A2: 1 | B2: Aircash | C2: aircash.eu | D2: Zagreb | E2: Fintech (e-money, Mastercard issuer) | F2: EU-licensed e-money institution: payments and money transfers | G2: 121 (FINA) / 146 (reputacija.hr (https://reputacija.hr/tvrtka/aircash)), €81.9M revenue 2025 | H2: In-house automation of partner settlement reconciliation, video verification, fraud prevention and reporting; building a Data/AI team (Netokracija (https://www.netokracija.com/aircash-o-ljudima-iza-poznate-fintech-aplikacije-u-potrazi-za-backendasima-197700)); moved AI for onboarding and risk monitoring from bought tools to in-house engineers (Lider (https://lidermedia.hr/tehno/hrvoje-cosic-za-vecinu-procesa-i-dalje-je-dovoljna-osnovna-tehnologija-a-ne-ai-159071)); finance ops growing on Business Central (LinkedIn job (https://hr.linkedin.com/jobs/view/manager-accounting-operations-m-f-at-aircash-4446436189)) | I2: E-money institution, so in DORA scope; hiring AML specialists (MojPosao (https://mojposao.hr/en/job/16e3bcb4-a057-11f0-805e-02d7d3e51677/specijalist-za-sprjecavanje-pranja-novca-m-z)) | J2: 2/1/2/2/1 | K2: 9 | L2: You moved AI for onboarding and risk monitoring in-house. ByteChef lets you run those agents with guardrails and human sign-off on your own servers, so customer and AML data never leaves your DORA perimeter, and finance-ops reconciliation runs in the same engine. | M2: target | N2: Hrvoje Ćosić (Director / CEO); Branimir Petrušić (Director of Product (one source says CTO; unverified)); Ivana Arambašić (Head of IT Operations (as of 2022)) | O2: =COUNTIF(Contacts!$B:$B,B2) -> 3
A3: 2 | B3: Alma Career Croatia | C3: mojposao.hr | D3: Zagreb | E3: HR tech / online jobs (Alma Media) | F3: Runs MojPosao, the largest Croatian jobs board | G3: 83 (2025) (reputacija (https://reputacija.hr/tvrtka/alma-career-croatia)) | H3: "Internal Tools Engineer" ad: build automations across M365/Slack, Power Platform scripting, REST integrations, and "champion the adoption of AI in IT Operations" (MojPosao (https://mojposao.hr/posao/0b4437dd-b346-11f1-9e17-0280a8fb46bd/internal-tools-engineer-m-f)) | I3: Candidate personal data across several countries (inferred) | J3: 2/2/3/1/1 | K3: 9 | L3: Saw you're hiring an Internal Tools Engineer to build M365/Slack automations and push AI into IT Ops. ByteChef gives that role one open-source, self-hosted engine for integrations and AI agents, with no per-task pricing. | M3: target | N3: Alen Mrvac (Country lead (title unverified)) | O3: =COUNTIF(Contacts!$B:$B,B3) -> 1
A4: 3 | B4: Plavi tim | C4: plavitim.hr | D4: Zagreb | E4: IT services (INA Group captive) | F4: INA Group's in-house IT company serving all INA members | G4: 162 (CompanyWall (https://www.companywall.hr/tvrtka/plavi-tim-doo/MMxkKcID)); parent group far larger | H4: UiPath RPA programme with 100+ robotic processes (plavitim.hr (https://plavitim.hr/en/project/projekt-rpa/)); RPA junior specialist ad (expired); current ad cites "advanced technologies for business-process automation" (LinkedIn (https://hr.linkedin.com/jobs/view/4468600056)) | I4: Energy critical infrastructure; on-prem and cloud | J4: 2/2/3/2/0 | K4: 9 | L4: With 100+ UiPath robots running for INA, an open-source engine you self-host (API workflows plus AI agents with human approvals, unmetered) could carry the next wave without per-robot licensing. | M4: target | N4: Kristian Schuster (Director (registry sources differ)) | O4: =COUNTIF(Contacts!$B:$B,B4) -> 1
A5: 4 | B5: HBOR | C5: hbor.hr | D5: Zagreb | E5: State development bank | F5: Croatia's development and export-credit bank, with its own IT sector | G5: 446 staff, end-2024 (annual report (https://www.hbor.hr/UserDocsImages/2025/04/Godi%C5%A1nji%20financijski%20izvje%C5%A1taji%20%202024.pdf?vel=4470859)) | H5: Its IT scholarship call names Kubernetes, Docker, SOA, BPM, Spring, Hibernate and Vaadin (HBOR (https://www.hbor.hr/natjecaj-za-studentske-stipendije)); has an application-support directorate | I5: State financial institution on its own Kubernetes/Docker; separate information-security function (contacts (https://www.hbor.hr/drugi-kontakti)); public procurement applies | J5: 2/2/2/2/0 | K5: 8 | L5: You already run Spring, BPM and SOA on your own Kubernetes. ByteChef is a Java/Spring workflow and AI-agent engine you can deploy on that same cluster, open source and with no per-task pricing. | M5: target | N5: Hrvoje Čuvalo (President of the Board (IT sector director not named publicly)) | O5: =COUNTIF(Contacts!$B:$B,B5) -> 1
A6: 5 | B6: Hypefy | C6: hypefy.ai | D6: Zagreb | E6: AI / martech scale-up | F6: AI agents for influencer marketing: campaigns, outreach, payments, reporting | G6: about 49; $7.2M Series A, Jun 2026 (NetInfluencer (https://www.netinfluencer.com/croatian-ai-influencer-marketing-platform-hypefy-raises-7-2m-usd-series-a/)) | H6: AI Engineer (AI Enablement) to automate Sales, Marketing, CS and Campaigns with "workflow agents", MCP servers, guardrails and evals on HubSpot, M365 and Azure (LinkedIn job (https://hr.linkedin.com/jobs/view/ai-engineer-ai-enablement-at-hypefy-4473149265)) | I6: Creator, contract and payment data (GDPR); internal agent volume grows with campaigns | J6: 2/2/2/1/1 | K6: 8 | L6: Your AI Enablement posting describes building workflow agents for every department. ByteChef gives that team an open-source, self-hosted engine where agents, HubSpot/M365 connectors and human approval steps live together, with no per-run pricing as usage scales. | M6: target | N6: Stjepan Zelić (Co-founder and CEO) | O6: =COUNTIF(Contacts!$B:$B,B6) -> 1
A7: 6 | B7: Njuškalo | C7: njuskalo.hr | D7: Zagreb | E7: Online marketplace (Styria) | F7: Croatia's largest classifieds marketplace, 1.1M+ active users | G7: 111–118; €17.8M revenue 2025 (Fina (https://infobiz.fina.hr/tvrtka/njuskalo-d-o-o/OIB-94718723416)); "almost 150" per a 2026 ad | H7: Hiring a Senior ML Engineer for an in-house data-science team on Airflow, dbt, MLflow, ClickHouse, AWS, Terraform (TalentLyft (https://njuskalo.talentlyft.com/jobs/machine-learning-engineer-HqY)); also hiring a Mid/Senior DWH Developer (job (https://hr.linkedin.com/jobs/view/mid-senior-dwh-developer-m-f-at-nju%C5%A1kalo-4472377381)), a CDP/event-taxonomy owner on Segment (job (https://hr.linkedin.com/jobs/view/senior-data-measurement-specialist-at-nju%C5%A1kalo-4464805884)) and a pricing & monetization expert (Jooble (https://hr.jooble.org/desc/-8515081775154551079)); PHP/Symfony backend; AI-assisted ad posting (VidiLAB (https://www.vidilab.com/vijesti/ostalo/5650-njuskalo-aplikacija-ai-predaja-oglasa-i-munjevito-pretrazivanje)) | I7: 1.1M users' personal data (GDPR, inferred) | J7: 2/2/2/1/1 | K7: 8 | L7: Saw you're hiring a Senior ML Engineer to run Airflow and dbt pipelines. ByteChef is open-source and self-hosted, so ops and AI-agent workflows can sit next to that stack in your own AWS, with no per-task pricing. | M7: target | N7: Mario Vrgoč (Director) | O7: =COUNTIF(Contacts!$B:$B,B7) -> 1
A8: 7 | B8: Ciklopea | C8: ciklopea.com | D8: Zagreb | E8: Translation / localisation | F8: Language-services provider for regulated industries, with its own Orchestrum TMS | G8: 20–29 staff + 1,000 external linguists (Adorio (https://www.adorio.hr/ciklopea)) | H8: Orchestrum TMS with CMS and SharePoint connectors "for workflow automation"; client portal with real-time tracking (ciklopea.com (https://ciklopea.com/hr/)) | I8: ISO 27001, 17100, 18587, 13485; regulated clients | J8: 2/1/2/2/1 | K8: 8 | L8: You already wire Orchestrum into CMSs and SharePoint under ISO 27001. ByteChef gives you 190+ self-hosted connectors and AI agents with human review, with no per-task fees and no client text leaving your servers. | M8: target | N8: Sandra Stojak (Founder / Director) | O8: =COUNTIF(Contacts!$B:$B,B8) -> 1
A9: 8 | B9: FORA Solutions (Master f&b) | C9: fora.solutions | D9: Zagreb | E9: Hospitality fintech / POS | F9: Digital menus, ordering and payment processing for restaurants and bars | G9: 14 (2025) (fininfo (https://www.fininfo.hr/Poduzece/Pregled/master-fb/Detaljno/785920)) | H9: Payment Support Team Coordinator must "identify opportunities for automation and reducing manual work" across onboarding, activation and incidents (MojPosao (https://mojposao.hr/posao/f1371f51-7231-404f-9f53-1096cc2f2a5a/payment-support-team-coordinator-m-z)) | I9: Payments: acquirers, providers, a compliance team | J9: 2/2/2/2/0 | K9: 8 | L9: Saw you're hiring a Payment Support lead tasked with cutting manual work in onboarding and incidents. ByteChef automates those flows self-hosted, keeping payment data in your own environment, with no per-task fees. | M9: target | N9: Ivan Brkić (Managing Director); Pero Pehar (CEO) | O9: =COUNTIF(Contacts!$B:$B,B9) -> 2
A10: 9 | B10: PREMIS | C10: portal.premis.hr | D10: Makarska | E10: Food manufacturing (ice-cream exporter) | F10: Family ice-cream maker selling across Europe | G10: 30–36 (2025) (reputacija.hr (https://reputacija.hr/tvrtka/premis)) | H10: Digital Automation Specialist ad names "n8n, Make.com, Zapier, Microsoft Power Automate, IFTTT", plus building AI agents (MojPosao (https://mojposao.hr/posao/c0ddda46-9df1-11f0-805e-02d7d3e51677/specijalist-za-digitalnu-automatizaciju-i-tehnolosku-podrsku-m-z), Premis (https://www.portal.premis.hr/zaposaljavamo-specijalist-ica-za-digitalnu-automatizaciju-i-tehnolosku-podrsku/)) | I10: Not stated; cost control for a small team on Workspace, M365, WooCommerce and Shopify | J10: 2/1/3/0/1 | K10: 7 | L10: Saw your automation-specialist ad lists n8n, Make, Zapier and Power Automate side by side, plus AI agents. ByteChef covers all of it in one open-source platform you self-host, so whatever your new hire builds never hits per-task pricing. | M10: target | N10: Toni Premeru / Branko-Silvio Premeru (Owner / Director (sources differ)) | O10: =COUNTIF(Contacts!$B:$B,B10) -> 1
A11: 10 | B11: KentBank | C11: kentbank.hr | D11: Zagreb | E11: Retail and SME bank | F11: Fast-growing universal bank, 16–17 branches | G11: 201–500 (LinkedIn (https://hr.linkedin.com/company/kentbank-d-d-)) | H11: Grew its software development and digital transformation team in 2025; KentPro PSD2 multi-bank app (Glas Slavonije (https://www.glas-slavonije.hr/novosti/ekonomija/2026/05/27/kentbank-ostvario-rekordne-rezultate-u-2025-godini-uz-snazan-rast-digitalnu-transformaciju-i-odrzivi-razvoj-766028/)); hiring developers (MojPosao (https://mojposao.hr/posao/d12efb24-8d70-11f0-b656-023e9d2b1e3d/samostalni-projektant-programer-m-z)) | I11: Took full ownership of its core banking system for "technological independence" (same source); bank, so DORA applies | J11: 2/1/2/2/0 | K11: 7 | L11: You took your core banking in-house to be technologically independent. ByteChef applies the same idea to process automation and AI agents: open source, inside your own infrastructure, no per-task fees. | M11: target | N11: Hasan Ecesoy (President of the Board; owns the IT and digital-transformation sectors) | O11: =COUNTIF(Contacts!$B:$B,B11) -> 1
A12: 11 | B12: JANAF | C12: janaf.hr | D12: Zagreb | E12: Energy (oil pipeline, critical infrastructure) | F12: Croatia's crude-oil pipeline and storage operator (majority state-owned) | G12: 441 (2025, FINA) | H12: Hiring "digital process associates" to define BPMN flows across ECM, DMS and ERP (MojPosao (https://mojposao.hr/posao/ebe571aa-19fa-11f0-9b44-028f65c884b5/suradnik-za-digitalne-procese-m-z), RITEH (https://riteh.uniri.hr/novosti/janaf-d-d-3-radna-mjesta/)) | I12: NIS2 energy sector; own security sector; public procurement | J12: 2/1/2/2/0 | K12: 7 | L12: Your digital-process team is mapping BPMN flows across ECM, DMS and ERP. ByteChef can run those flows, plus AI steps with human approval, entirely on JANAF's own network. | M12: target | N12: Stjepan Adanić (President of the Board) | O12: =COUNTIF(Contacts!$B:$B,B12) -> 1
A13: 12 | B13: AGRIVI | C13: agrivi.com | D13: Zagreb | E13: Agritech SaaS | F13: Farm-management software with an "AI Engage" product line | G13: about 39 (Jun 2026) | H13: Open AI & Automation Engineer role to "drive AGRIVI's internal AI adoption, building the agents and automation that shape how we operate" (TalentLyft (https://agrivi.talentlyft.com/jobs/ai-automation-engineer-fm-ciXf)) | I13: Not stated (Azure stack) | J13: 2/1/3/0/1 | K13: 7 | L13: You're hiring someone to build internal agents and automation from scratch. ByteChef gives that engineer a ready open-source agent and workflow engine with guardrails and approvals, self-hosted and with no per-execution fees. | M13: target | N13: Guillaume Rabhi (Chief Digital Officer (the AI & Automation role reports to him)); Matija Žulj (Founder and CEO) | O13: =COUNTIF(Contacts!$B:$B,B13) -> 2
... A20: 19 | B20: J&T banka | C20: jtbanka.hr | D20: Varaždin | E20: Banking | F20: Small J&T-owned bank running its own integrated core system, OLBIS | G20: 55 (end-2024) (annual report (https://www.jtbanka.hr/UserDocsImages/2025/JT%20godi%C5%A1nje%20izvje%C5%A1%C4%87e%202024%20HRV_FINAL.pdf)) | H20: Develops OLBIS in-house for regulatory reporting and instant payments, has added Vestigo for instant payments, and plans an online deposit/mobile/onboarding platform within 12–15 months (same source) | I20: Credit institution under DORA; 2024 infrastructure focus on monitoring and vulnerability checks | J20: 2/1/2/2/0 | K20: 7 | L20: Your 2024 report says you're adding an online onboarding and deposit platform next to OLBIS and Vestigo. ByteChef is open source and runs inside your own perimeter, so you can connect those systems and automate onboarding and reporting with AI agents and human approvals, at no per-task fees. | M20: target | N20: Hrvoje Draksler (President of the Board) | O20: =COUNTIF(Contacts!$B:$B,B20) -> 1
A21: 20 | B21: Hidrocibalae | C21: hidrocibalae.hr | D21: Vinkovci | E21: Energy services (offshore survey data) | F21: Processes hydrographic and geophysical survey data for offshore wind, oil & gas and marine construction | G21: 60 / "70+" (CompanyWall (https://www.companywall.hr/pretraga?n=hidrocibalae)) | H21: Hired a Head of Technology to run R&D and IT strategy (MojPosao (https://mojposao.hr/posao/45658dab-6ba4-11f0-8b41-023a0724bf89/head-of-technology-m-z)); says it runs 200+ automated solutions in Python and its own Marelia platform (site (https://www.hidrocibalae.hr/)) | I21: Confidential client survey data (inferred) | J21: 2/2/2/1/0 | K21: 7 | L21: Saw you're hiring a Head of Technology to set the IT strategy behind your 200+ automations. ByteChef could run your internal ops workflows and AI agents next to Marelia, self-hosted, with no per-task fees. | M21: target | O21: =COUNTIF(Contacts!$B:$B,B21) -> 0
A22: 21 | B22: Montelektro | C22: montelektro.hr | D22: Kastav | E22: Industrial automation / MES | F22: Process-control integrator; makes the Digital Factory Portal MES and BatchME (130+ breweries) | G22: 226 (CompanyWall (https://www.companywall.hr/pretraga?n=montelektro)) | H22: Hired an "engineer for business IT systems" (SQL, accounting/finance processes), Jul 2026 (MojPosao (https://mojposao.hr/posao/c9644416-7530-11f1-9e17-0280a8fb46bd/inzenjer-za-poslovne-it-sustave-m-z)); R&D lead ad on "integrating AI technologies into business systems" (LinkedIn (https://hr.linkedin.com/jobs/view/4470871035)) | I22: On-prem factory culture (inferred) | J22: 2/2/2/1/0 | K22: 7 | L22: Saw you were hiring an engineer for business IT systems. ByteChef could link your finance and ERP back office without per-task pricing, and it self-hosts like the factory stacks you deliver. | M22: target | N22: Mario Županović (CEO); Krešimir Bušić (Director of Automation and Innovation) | O22: =COUNTIF(Contacts!$B:$B,B22) -> 2
A23: 22 | B23: Končar – Institut za elektrotehniku | C23: koncar-institut.hr | D23: Zagreb | E23: Electrical-engineering R&D / testing (Končar group) | F23: R&D and testing institute; transformer/machine monitoring and rail ICT | G23: 234 (CompanyWall (https://www.companywall.hr/pretraga?n=kon%C4%8Dar%20institut%20za%20elektrotehniku)) | H23: Hiring mid and senior .NET developers (MojPosao (https://mojposao.hr/posao/75676245-b592-11f1-9e17-0280a8fb46bd/mid-net-software-developer-m-f)); runs a Digital Factory Lab Industry 4.0 initiative (DFL (https://www.koncar-institut.hr/digital-factory-lab/)) | I23: Monitoring for power plants and rail (critical infrastructure) | J23: 2/2/2/1/0 | K23: 7 | L23: Saw you're growing the .NET team and running the Digital Factory Lab. ByteChef is an open-source automation and AI-agent engine you can host on-prem, so lab and monitoring data never leaves your network. | M23: target | N23: Dalibor Filipović-Grčić (Director) | O23: =COUNTIF(Contacts!$B:$B,B23) -> 1
A24: 23 | B24: Zagrel Rittmeyer | C24: zagrel.hr | D24: Zagreb | E24: SCADA / IoT for water and energy utilities | F24: Automation and SCADA integrator for water utilities (Swiss Rittmeyer/Brugg group) | G24: 25 (CompanyWall (https://www.companywall.hr/pretraga?n=zagrel%20rittmeyer)) | H24: DevOps engineer ad: Azure plus local servers, "process automation using PowerShell and Python" (tportal (https://www.tportal.hr/tehno/clanak/trazite-posao-u-it-sektoru-pogledajte-koje-tvrtke-zaposljavaju-20251003)); IoT Solution Owner hire | I24: Water-utility clients are NIS2 essential entities | J24: 2/2/2/1/0 | K24: 7 | L24: Saw you're hiring DevOps to automate processes with PowerShell and Python. ByteChef turns those scripts into governed, self-hosted workflows with AI agents and approvals, at no per-run cost. | M24: target | O24: =COUNTIF(Contacts!$B:$B,B24) -> 0
A25: 24 | B25: Hendal | C25: hendal.hr | D25: Zagreb | E25: Market research | F25: Croatian-owned research and polling agency since 1993; Eurobarometer partner | G25: 17–18 staff + 400 field interviewers (Fina (https://infobiz.fina.hr/tvrtka/hendal-d-o-o/OIB-35357386687)) | H25: F2F, CATI, CAWI and an online panel processed in SPSS, Q and R; launched "Henri", an AI platform over client research data (hendal.hr (https://www.hendal.hr/)) | I25: ISO 20252, ISO 9001, GDPR, ESOMAR | J25: 2/1/1/2/1 | K25: 7 | L25: Henri shows you're putting AI on top of 30 years of survey data. ByteChef can automate the CATI/CAWI-to-SPSS/R pipeline and run AI agents on your own server, which fits ISO 20252 and GDPR, with no per-run pricing. | M25: target | O25: =COUNTIF(Contacts!$B:$B,B25) -> 0
A26: 25 | B26: Identyum | C26: identyum.com | D26: Varaždin | E26: RegTech / digital identity | F26: KYC/AML onboarding, ID wallet, e-signature and open-banking AML (FinCheck) for banks, pension funds and fintechs | G26: 11–50 (LinkedIn (https://hr.linkedin.com/company/identyum)) | H26: Hiring a support lead for a 5-person tier-1/2 team on Jira, Slack, email and Graylog; engineering stack is Java Spring Boot, OAuth 2.0, PostgreSQL, OpenSearch (job ad (https://hr.linkedin.com/jobs/view/voditelj-tehni%C4%8Dke-podr%C5%A1ke-klijentima-fizi%C4%8Dkim-osobama-slu%C5%BEbenik-za-identifikaciju-m-%C5%BE-at-identyum-4472147188)) | I26: eIDAS, GDPR, PSD2, AML, AISP licence, ISO 27001 (site (https://www.identyum.com/)) | J26: 2/2/1/2/0 | K26: 7 | L26: Saw you're hiring a support lead to run tier-1/2 on Jira, Slack and email. ByteChef is open-source and Java/Spring like your stack, self-hosts inside your ISO 27001 perimeter, and can automate ticket triage, KYC-case escalation and log-to-ticket flows with AI agents and human approvals, with no per-task fees. | M26: target | N26: Robert Ilijas (CEO); Tomislav Bošnjaković (COO) | O26: =COUNTIF(Contacts!$B:$B,B26) -> 2
A27: 26 | B27: Solflare | C27: solflare.com | D27: Zagreb | E27: Crypto (self-custody wallet) | F27: Solana wallet with about 4M monthly users and $20B+ in assets | G27: about 140–161 (LinkedIn (https://hr.linkedin.com/company/solflare)) | H27: Senior Data Engineer for ETL/ELT from databases and APIs (BigQuery, dbt Cloud, PostHog, Dune, Metabase); "Claude Code is deeply integrated" in daily work (job ad (https://hr.linkedin.com/jobs/view/senior-data-engineer-at-solflare-4468230609)) | I27: Security-critical custody product (inferred) | J27: 2/1/2/1/1 | K27: 7 | L27: Saw you're hiring a Senior Data Engineer to pull APIs and on-chain data into BigQuery, and that Claude Code is already part of daily work. ByteChef is an open-source workflow and AI-agent engine you can self-host next to your wallet infrastructure, with unmetered runs for ops and data glue. | M27: target | N27: Vidor Gencel (Co-founder) | O27: =COUNTIF(Contacts!$B:$B,B27) -> 1
A28: 27 | B28: HOK osiguranje | C28: hok-osiguranje.hr | D28: Zagreb | E28: Insurance | F28: Croatian non-life/motor insurer selling mainly through its own network | G28: 294 (2024 avg) (GFI 2024 (https://www.hok-osiguranje.hr/wp-content/uploads/2025/05/Godisnji-financijski-izvjestaji-za-2024.-godinu-s-misljenjem-aktuara.pdf)) | H28: 2025 SFCR targets "further digitalisation and acceleration" of claims; internal controls already partly "through automated work processes" (SFCR 2025 (https://www.hok-osiguranje.hr/wp-content/uploads/2026/04/Izvjesce-o-solventnosti-i-financijskom-stanju-2025.pdf)) | I28: Solvency II, DORA; named information-security officer | J28: 2/1/2/2/0 | K28: 7 | L28: Your 2025 SFCR names faster, more digital claims settlement as a priority. ByteChef is open-source automation with AI agents that runs on your own servers, so claims workflows stay in-house for DORA and there is no per-task fee. | M28: target | N28: Hrvoje Pezić (President of the Board (covers IT)) | O28: =COUNTIF(Contacts!$B:$B,B28) -> 1
A29: 28 | B29: Solvera stambena štedionica | C29: solverastedionica.hr | D29: Zagreb | E29: Housing savings bank (Slatinska banka group) | F29: Former Wüstenrot housing savings bank, acquired and rebranded in 2025 | G29: 138 (Dec 2025) (annual report (https://www.solverastedionica.hr/UserDocsImages/SOLVERA%20DOC%20pdf/SOLVERA%20GI%202025%20kona%C4%8Dno.pdf?vel=2658032)) | H29: IT migration from the legacy CICS system to a new Solvera system; adjusting business processes (same source) | I29: HNB-supervised, DORA; bank-group integration | J29: 2/1/2/2/0 | K29: 7 | L29: Moving off CICS and into the Slatinska banka group creates a lot of system-to-system work. ByteChef can automate those flows, with AI agents, entirely on your own infrastructure and with no per-task pricing. | M29: target | N29: Boris Zadro (President of the Board) | O29: =COUNTIF(Contacts!$B:$B,B29) -> 1
A30: 29 | B30: Porsche Leasing | C30: porscheleasing.com.hr | D30: Zagreb | E30: Leasing (Porsche Bank group) | F30: Croatian vehicle-leasing arm of Porsche Bank AG | G30: 77 (2025) (poslovna.hr (https://www.poslovna.hr/lite/porsche-leasing/225428/subjekti.aspx?AspxAutoDetectCookieSupport=1)) | H30: Hired a "project manager for digitalisation and process optimisation" (ad from 2021) (MojPosao (https://mojposao.hr/posao/b744405e-a610-11ee-9a53-02d5740d71bf/Voditelj-projekta-na-podrucju-digitalizacije-i-optimizacije-procesa-mz?source=old)) | I30: HANFA-regulated; group IT governance | J30: 2/1/2/2/0 | K30: 7 | L30: Your digitalisation and process-optimisation work has a natural next step: ByteChef gives that team an open-source, self-hosted engine with AI agents to automate leasing back-office flows, with no per-task fees. | M30: target | N30: Danijel Pasarić (Director) | O30: =COUNTIF(Contacts!$B:$B,B30) -> 1
A31: 30 | B31: Erste Group Card Processor | C31: egcp.com | D31: Zagreb | E31: Card processing (Erste group) | F31: Erste Group's card-processing IT company: digital cards, AI fraud prevention | G31: 141 (2025) (poslovna.hr (https://poslovna.hr/lite/erste-group-card-processor/90011/subjekti.aspx)) | H31: Java, Angular, OpenShift and Kubernetes stack (ITJobsCroatia (https://itjobscroatia.com/companies/Xy573xAltc)); ops and data flows across group entities (inferred) | I31: PCI DSS and DORA; runs its own OpenShift | J31: 2/2/1/2/0 | K31: 7 | L31: You already run Java on your own OpenShift. ByteChef is a Java/Spring open-source automation and AI-agent engine you can deploy on that same platform, so PCI-scoped workflows never leave it and there is no per-execution fee. | M31: target | N31: Kristina Zver (Head of Operations) | O31: =COUNTIF(Contacts!$B:$B,B31) -> 1
A32: 31 | B32: Sunčani Hvar | C32: suncanihvar.com | D32: Hvar | E32: Hotel group | F32: 8-hotel group on Hvar (Bahraini-owned); €43.5M revenue | G32: 363 (FINA 2025) (Fina (https://infobiz.fina.hr/subjekt/suncani-hvar-d-d/OIB-29834131149)) | H32: IT Director and in-house IT; centralised all 8 hotels on one platform to roll out group-wide services; smart-room plans (UHPA (https://www.uhpa.hr/hr/vijesti/digitalna-revolucija-na-hvaru)) | I32: Runs its own on-prem compact data centre with a security gateway (Kongres (https://kongres-magazine.eu/2026/02/suncani-hvar-and-m3connect-set-new-standards-in-it-infrastructure/)) | J32: 2/1/2/2/0 | K32: 7 | L32: You just centralised all eight hotels onto your own on-prem data centre. ByteChef is open-source automation and AI agents you can run in that same data centre, with no per-task pricing, to connect PMS, POS and guest services group-wide. | M32: target | N32: Zdravko Tudor (IT Director) | O32: =COUNTIF(Contacts!$B:$B,B32) -> 1
A33: 32 | B33: Infomare | C33: infomare.hr | D33: Zagreb | E33: Software (ERP for public sector) | F33: 30-year ERP vendor, mainly for the Croatian public sector | G33: 48 (2024) (reputacija (https://reputacija.hr/tvrtka/infomare)) | H33: Junior DevOps hire spending about 70% of the time on automation (LinkedIn (https://hr.linkedin.com/jobs/view/4472595979)) | I33: Public-sector ERP customers (data residency) | J33: 2/2/1/2/0 | K33: 7 | L33: Saw you're hiring a DevOps engineer to drive automation. An open-source automation engine your public-sector ERP clients can run on-prem, with no per-execution pricing, could extend that work into your products and your own back office. | M33: target | N33: Damir Kaknjo (IT Manager); Goran Novak (CEO) | O33: =COUNTIF(Contacts!$B:$B,B33) -> 2
A34: 33 | B34: Zagrebačka burza (ZSE) | C34: zse.hr | D34: Zagreb | E34: Capital-markets infrastructure | F34: Croatian stock exchange (also owns the Ljubljana exchange) | G34: 24 (d.d.) / 37 (group), end-2025 (annual report (https://eho.zse.hr/fileadmin/issuers/ZB/FI-ZB-07f3af13f5fa32c6206514c14c83c1c5.pdf)) | H34: Fully digitalised listing-document submission (Nov 2025); in-house IT "actively working to reduce costs and the need for external vendors" (same source) | I34: DORA implementation through 2026. FINA has announced a takeover intent, which could move IT decisions | J34: 2/1/1/2/0 | K34: 6 | L34: Your IT team is cutting external vendors while implementing DORA. ByteChef is open-source automation and AI agents you run yourself: no new SaaS vendor and no per-task pricing. | M34: target | N34: Ivana Gažić (President of the Board) | O34: =COUNTIF(Contacts!$B:$B,B34) -> 1
A35: 34 | B35: Istarska kreditna banka (IKB) | C35: ikb.hr | D35: Umag | E35: Regional bank | F35: Istrian regional bank, also in Primorje-Gorski Kotar and Zagreb | G35: 223 (end-2025) | H35: IT sector hiring a programmer, a sysadmin and an IT security analyst (MojPosao (https://mojposao.hr/posao/f0edc226-acc5-11ef-8ae2-02862c3d2b49/programer-m-z)) | I35: Bank (DORA); runs its own servers. New CEO from Feb 2027 | J35: 2/1/1/2/0 | K35: 6 | L35: IKB runs its own servers and is building its in-house programming team. ByteChef adds open-source process automation and AI agents to that stack, on-prem and DORA-friendly, with no per-task licence. | M35: target | N35: Tomislav Jeletić (Incoming CEO (from Feb 2027)) | O35: =COUNTIF(Contacts!$B:$B,B35) -> 1
A36: 35 | B36: Electrocoin | C36: electrocoin.eu | D36: Zagreb | E36: Crypto (CASP) / crypto payments | F36: Croatia's first Bitcoin exchange; first Croatian MiCA licence (Apr 2026) | G36: 29 (2025, FINA) | H36: In-house engineering on Python/Django and React | I36: First MiCA CASP in Croatia (HANFA (https://www.hanfa.hr/news/hanfa-board-meeting-electrocoin-doo-becomes-the-first-company-to-obtain-hanfa-s-authorisation-to-operate-in-accordance-with-mica/)); in DORA scope | J36: 2/1/1/2/0 | K36: 6 | L36: Now that you're fully supervised under MiCA and DORA, ByteChef can automate compliance and ops workflows, with AI review steps and human approval, on infrastructure you control. | M36: target | N36: Nikola Škorić (Co-founder) | O36: =COUNTIF(Contacts!$B:$B,B36) -> 1
A37: 36 | B37: Poliklinika Salvea | C37: poliklinika-salvea.hr | D37: Zagreb | E37: Private healthcare (paediatrics; Salveo CEE group) | F37: Fast-growing paediatric polyclinic | G37: 26 (FINA) | H37: Launched Croatia's first AI WhatsApp booking agent with Datum; waitlist, missed-call and transport workflows planned (Lider (https://lidermedia.hr/info/salvea-i-datum-razvili-prvog-ai-agenta-za-narucivanje-u-zdravstvu/)) | I37: Agent described as a "closed, secure and fully controlled system"; health data under GDPR | J37: 2/0/2/1/1 | K37: 6 | L37: Your booking agent is already a closed, controlled system. ByteChef lets you add waitlist, missed-call and transport workflows with guardrails and staff approval, all inside your own environment. | M37: target | N37: Marija Bošnjak (Director) | O37: =COUNTIF(Contacts!$B:$B,B37) -> 1
... A49: 48 | B49: InterCapital | C49: inter.capital | D49: Zagreb | E49: Investment banking / asset management | F49: Independent CEE investment firm; the region's only Eurex member | G49: 51–200 (LinkedIn (https://hr.linkedin.com/company/intercapital)) | H49: Set up InterCapital Digital Wealth Management in May 2025 (CompanyWall (https://www.companywall.hr/tvrtka/intercapital-digital-wealth-management-doo/MMUPrUiq)); runs the "Genius" digital product | I49: Investment firm under DORA | J49: 2/1/1/2/0 | K49: 6 | L49: With the new digital wealth business and Genius, ByteChef can automate onboarding, KYC and reporting flows with AI agents on your own infrastructure, which is DORA-friendly and has no per-task fees. | M49: target | N49: Ivan Kurtović (CEO) | O49: =COUNTIF(Contacts!$B:$B,B49) -> 1
A50: 49 | B50: GA Croatia | C50: unknown (Renault importer per ad) | D50: Zagreb | E50: Automotive import / distribution | F50: High-revenue automotive distributor with a small team | G50: 53 (CompanyWall (https://www.companywall.hr/pretraga?n=ga%20croatia)) | H50: "Business Process Development Specialist" to run process-automation projects on Power Platform and SharePoint, Jun 2026 (MojPosao (https://mojposao.hr/posao/62a2b31b-83a4-4d0a-bf8c-b85ba14a8d34/strucnjak-za-razvoj-poslovnih-procesa-m-z)) | I50: unknown | J50: 2/1/3/0/0 | K50: 6 | L50: Saw you're hiring someone to run process automation on Power Platform. ByteChef is an open-source alternative with AI agents and approvals built in and no per-flow licensing. | M50: target | O50: =COUNTIF(Contacts!$B:$B,B50) -> 0
A51: 50 | B51: Plinacro | C51: plinacro.hr | D51: Zagreb | E51: Gas transmission operator (state-owned) | F51: National gas TSO | G51: 263 (2024) (Fina (https://infobiz.fina.hr/tvrtka/plinacro-d-o-o/OIB-69401829750)) | H51: ICT and information-security specialist calls, Aug–Sep 2026 (archive (https://www.plinacro.hr/default.aspx?id=120)) | I51: NIS2 essential entity; dedicated information-security sector | J51: 2/1/1/2/0 | K51: 6 | L51: Saw you're adding ICT and cybersecurity staff this autumn. ByteChef runs fully on-prem with audit trails and human approvals, so you can automate internal workflows within NIS2 rules. | M51: target | N51: Ivan Radoš (Director, Information Security) | O51: =COUNTIF(Contacts!$B:$B,B51) -> 1
A52: 51 | B52: Jadranska vrata (AGCT) | C52: ictsi.hr | D52: Rijeka | E52: Container terminal | F52: Rijeka container terminal (ICTSI 51%, Luka Rijeka 49%) | G52: 232 (CompanyWall (https://www.companywall.hr/pretraga?n=jadranska%20vrata)) | H52: Runs NAVIS N4 TOS, Portunus truck appointments and a customer portal side by side (site (https://www.ictsi.hr/en/onama)) | I52: Port operator, NIS2 transport; foreign-controlled, so check local IT autonomy | J52: 2/1/1/2/0 | K52: 6 | L52: With NAVIS, Portunus and your customer portal all running side by side, ByteChef can move data between them and run AI agents in your own environment, with no per-execution fees. | M52: target | N52: Goran Manfreda (Management Board) | O52: =COUNTIF(Contacts!$B:$B,B52) -> 1
A53: 52 | B53: Radnik | C53: radnik.hr | D53: Križevci | E53: Construction (+ quarrying, gas supply, transport) | F53: Construction and hydro-engineering group with 7 subsidiaries, active in HR and DE | G53: 350–415 (CompanyWall (https://www.companywall.hr/pretraga?n=radnik%20d.d.)) | H53: Hired a Head of IT to organise the department and lead information-system rollouts (MojPosao (https://mojposao.hr/posao/68408451-d31d-11ef-a705-02f6c82cbffd/voditelj-informatike-m-z)) | I53: Gas-supply line falls under NIS2 energy (inferred) | J53: 2/1/2/1/0 | K53: 6 | L53: Saw you recently built out an IT department to roll out information systems across the group. ByteChef could link construction, quarry, gas and hospitality systems in one self-hosted engine. | M53: target | N53: Mirko Habijanec (President of the Board) | O53: =COUNTIF(Contacts!$B:$B,B53) -> 1
A54: 53 | B54: Luka Ploče | C54: luka-ploce.hr | D54: Ploče | E54: Port operator | F54: Bulk and general cargo port with forwarding, shipping and marine-service subsidiaries | G54: 355 (CompanyWall (https://www.companywall.hr/pretraga?n=luka%20plo%C4%8De)) | H54: In-house e-transaction portal and IT support department (site (https://www.luka-ploce.hr/)) | I54: Port operator, NIS2 transport | J54: 2/1/1/2/0 | K54: 6 | L54: Your e-portal plus three subsidiaries means a lot of data to pass around. ByteChef automates that on your own servers with AI agents and no per-task cost. | M54: target | N54: Marin Bodrušić (Board member, finance and IT) | O54: =COUNTIF(Contacts!$B:$B,B54) -> 1
A55: 54 | B55: KOER | C55: koer.com | D55: Zagreb | E55: Energy (virtual power plant / BESS) | F55: Built Croatia's first virtual power plant | G55: 18 (CompanyWall (https://www.companywall.hr/pretraga?n=koer)) | H55: Hiring a senior .NET developer for its energy software, Aug 2026 (tportal (https://www.tportal.hr/tehno/clanak/it-jevci-trazite-posao-provjerili-smo-tko-zaposljava-i-sto-se-nudi-20260801)) | I55: Regulated grid-flexibility services (inferred) | J55: 2/2/1/1/0 | K55: 6 | L55: Saw you're hiring a senior .NET dev for the VPP platform. ByteChef could run your back-office and operator workflows and AI agents self-hosted, so your engineers can stay on the core platform. | M55: target | O55: =COUNTIF(Contacts!$B:$B,B55) -> 0
A56: 55 | B56: HNK Hajduk | C56: hajduk.hr | D56: Split | E56: Sports club | F56: Football club with about 119k members, run with the Naš Hajduk association | G56: 95–120 (Fina (https://infobiz.fina.hr/tvrtka/hnk-hajduk-s-d-d/OIB-04785516590)) | H56: Naš Hajduk recruiting a Salesforce CRM analyst/admin (nashajduk.hr (https://nashajduk.hr/)); membership runs on Salesforce, built with Maven Mule (Nacional (https://www.nacional.hr/tehnoloski-pogled-na-clanstvo-u-hajduku/)) | I56: Personal data of about 119k members | J56: 2/1/2/1/0 | K56: 6 | L56: Saw Naš Hajduk is looking for a Salesforce CRM analyst/admin. ByteChef is open-source and self-hosted, and it can sync Salesforce with ticketing, the web shop and payments for 119k members, with no per-task bill. | M56: target | N56: Teo Prkić (Head of Membership (2021)) | O56: =COUNTIF(Contacts!$B:$B,B56) -> 1
A57: 56 | B57: Terrakom | C57: terrakom.hr | D57: Zagreb | E57: Telecom / ISP | F57: Independent cable ISP: internet, phone, TV | G57: 25; €8.1M revenue 2025 (Fina (https://infobiz.fina.hr/tvrtka/terrakom-d-o-o/OIB-29050776382)) | H57: Self-built ordering and availability platform; provisioning, billing and support at about 25k households with 25 staff (inferred) (Lider (https://lidermedia.hr/aktualno/tvrtke-i-trzista/poslovna-scena/terrakom-srezali-troskove-ulozili-u-infrastrukturu-i-rasli-za-213-posto-126136/)) | I57: Own data centre; regulated telecom operator | J57: 2/1/1/2/0 | K57: 6 | L57: A 25-person ISP with its own data centre is the ideal place to self-host ByteChef. It can automate order-to-activation, billing and support tickets with no per-task fees. | M57: target | N57: Igor Tatarević (Owner / Director) | O57: =COUNTIF(Contacts!$B:$B,B57) -> 1
...

Sheet Partners
A1: # | B1: company | C1: url | D1: city | E1: type | F1: one-line_description | G1: est._size | H1: automation_practice_evidence | I1: partnership_angle | J1: score_breakdown | K1: score | L1: suggested_first-line_hook | M1: contacts | N1: n_contacts | O1: owner | P1: contact_email | Q1: touch1_date | R1: followup_date | S1: breakup_date | T1: replied | U1: call_booked | V1: call_held | W1: status | X1: notes
A2: 1 | B2: CROZ | C2: croz.net | D2: Zagreb | E2: IT consultancy / SI | F2: Digital-transformation consultancy for finance and public sector (also Munich) | G2: 194 (d.o.o., 2025); about 295 total (companywall (https://www.companywall.hr/tvrtka/croz-doo/MM15fwo0)) | H2: IBM partner for Process Automation, App Connect, API Connect, webMethods and watsonx Orchestrate (IBM Partner Plus (https://www.ibm.com/partnerplus/directory/company/1162)); Red Hat/HashiCorp partner; Claude Partner Network (croz.net (https://croz.net/)) | I2: An open-source, self-hostable tier for mid-market clients that won't pay IBM middleware prices; fits their Red Hat/OSS posture | J2: 3/2/1/2/1 | K2: 9 | L2: Your IBM App Connect and Process Automation practice serves banks well. ByteChef lets you take the same orchestration-plus-AI-agents work to mid-market clients on a self-hosted, open-source stack with no licence to start. | M2: Vjekoslav Jadrešić (Management Board member); Krešimir Mudrovčić (Management Board member) | N2: =COUNTIF(Contacts!$B:$B,B2) -> 2
A3: 2 | B3: Notch (formerly Agency04) | C3: wearenotch.com | D3: Zagreb | E3: Java/AI dev consultancy | F3: Senior engineering firm: custom software, AI agents, BPM integrations | G3: 170+ (about (https://wearenotch.com/about)) | H3: Camunda BPM integration service (https://wearenotch.com/service/camunda-bpm-integration/); Beeline integration on Java/Spring/Camunda (case (https://wearenotch.com/customer-stories/beeline-bpm-integration/)). Sells its own "Sovera AI" orchestration platform, which overlaps | I3: Spring shop that could extend ByteChef natively; about 80% of revenue is DACH/US | J3: 3/1/1/2/1 | K3: 8 | L3: You already build Camunda and Spring integrations for Beeline-scale clients. ByteChef is a Spring-based, open-source workflow and AI-agent platform your engineers can extend natively and run self-hosted for clients who need unmetered automation. | M3: Ivan Belić (CEO); Marko Štefančić (CTO) | N3: =COUNTIF(Contacts!$B:$B,B3) -> 2
A4: 3 | B4: Kodilion | C4: kodilion.hr | D4: Zagreb | E4: Java/DevOps software services; Red Hat/IBM/Elastic partner | F4: Enterprise software, system services and QA for government, banking and transport; ISO 9001/27001 | G4: 42 / "beyond 50" (Tracxn (https://tracxn.com/d/companies/kodilion/__7CP4vBp3NaERtRdbtEepu3e9r4MP8XEX6rARVq7rVa0), company (https://kodilion.hr/company/)) | H4: Built NSCP, a national transport data exchange, and worked on Croatian instant payments (kodilion.hr (https://kodilion.hr/)); about 50% of work is Java, with Spring (Clutch (https://clutch.co/profile/kodilion)) | I4: Java/Spring and Red Hat shop that could extend ByteChef for government and fintech clients needing on-prem | J4: 2/2/2/1/1 | K4: 8 | L4: Kodilion already builds Java/Spring data exchanges like NSCP for regulated clients. ByteChef is an open-source, Spring-based workflow and AI-agent engine you can self-host on their OpenShift, with no per-task pricing. | M4: Hinko-Ivan Sečen (Co-founder); Luka Ostović (Co-founder) | N4: =COUNTIF(Contacts!$B:$B,B4) -> 2
A5: 4 | B5: FrodX | C5: frodx.com | D5: Ljubljana / Zagreb | E5: HubSpot + Dynamics consultancy | F5: Martech/CRM consultancy (HubSpot Platinum) for SEE banking, insurance and B2B | G5: 45 (HubSpot directory (https://ecosystem.hubspot.com/marketplace/solutions/croatia)) | H5: HubSpot automation and integrations; AI agents for support, prospecting and voice; GEN-I email-triage and process-automation case (AI agents (https://frodx.com/en/ai-agents-and-frodx)) | I5: Automation across HubSpot, Dynamics and core systems, without per-task iPaaS fees | J5: 3/0/2/1/1 | K5: 7 | L5: Your GEN-I email-triage and HubSpot AI-agent work shows clients want automation beyond the CRM. ByteChef gives FrodX a self-hosted, open-source automation and agent layer for SEE banks and insurers, with no licence to start. | M5: Igor Pauletič (Co-founder and CEO) | N5: =COUNTIF(Contacts!$B:$B,B5) -> 1
A6: 5 | B6: Infinum | C6: infinum.com | D6: Zagreb | E6: Product/AI consultancy | F6: Design and engineering consultancy with an AI and data practice | G6: 244 (HR entity); 350+ overall | H6: AI agent development (https://infinum.com/artificial-intelligence/agent-development/) ("Agentic Sprint"); AI automation (https://infinum.com/blog/ai-automation/) article; no named iPaaS | I6: A governed production runtime with human-in-the-loop for the agents they prototype | J6: 2/1/1/2/1 | K6: 7 | L6: Your Agentic Sprint gets clients to a working agent in 10 days. ByteChef gives Infinum an open-source, self-hostable runtime with human-in-the-loop approvals to run those agents in production without metered execution. | M6: Nikola Kapraljević (CEO) | N6: =COUNTIF(Contacts!$B:$B,B6) -> 1
A7: 6 | B7: Provexio | C7: provexio.hr | D7: Sveti Martin na Muri | E7: Automation / dev agency | F7: Croatian agency selling RPA and AI automation, software and SEO | G7: unknown | H7: Names Zapier, Make and n8n, plus OpenAI/Claude/LangChain/RAG and HubSpot/Salesforce/Pipedrive/SAP integrations (page (https://provexio.hr/automatizacija-poslovanja)) | I7: Already sells iPaaS automation to Croatian SMBs; ByteChef replaces the metered tools in their margin | J7: 3/1/2/0/1 | K7: 7 | L7: You already build Zapier, Make and n8n automations for Croatian SMBs. ByteChef lets Provexio deliver the same with self-hosted, unmetered execution and AI agents, open source so there's no licence to start. | N7: =COUNTIF(Contacts!$B:$B,B7) -> 0
A8: 7 | B8: Notus IT | C8: notus.hr | D8: Zagreb | E8: Odoo Silver partner + custom dev | F8: Odoo implementation, localisation and custom apps for SMEs (10–300+ Odoo users) | G8: 16–19 (Fina (https://infobiz.fina.hr/tvrtka/notus-it-d-o-o/OIB-61839748667)) | H8: Connects Odoo to VoIP, biometrics, logistics, WMS, CMS, e-commerce and payment gateways (notus.hr (https://notus.hr/en/odoo)); 24 Odoo references | I8: Replace one-off Odoo connector code with reusable workflows; add AI agents for Odoo clients | J8: 3/1/2/1/0 | K8: 7 | L8: Your team hand-builds Odoo links to WMS, VoIP and payment gateways. ByteChef could turn those into reusable, self-hosted workflows with AI agents on top, at no per-task cost. | M8: Filip Žić (Owner) | N8: =COUNTIF(Contacts!$B:$B,B8) -> 1
A9: 8 | B9: Appliment | C9: appliment.eu | D9: Zagreb | E9: Bitrix24 Gold + Zoho partner | F9: CRM/DMS/WMS/BI implementations; Bitrix24 cloud and on-premise | G9: unknown; "110+ systems implemented" (appliment.eu (https://appliment.eu/)) | H9: "500+ automated processes"; Business Process Consulting and Business Automation services (appliment.eu (https://appliment.eu/), zoho (https://zoho.appliment.eu/hr/)) | I9: Cross-system layer between Bitrix24/Zoho and client ERPs; on-prem Bitrix clients suit self-hosting | J9: 3/1/2/1/0 | K9: 7 | L9: 500+ automated processes across Bitrix24 and Zoho is a lot of glue. ByteChef gives you one open-source, self-hostable engine for it, with AI agents and no per-task fees. | M9: Zvonimir Tokić (Director) | N9: =COUNTIF(Contacts!$B:$B,B9) -> 1
A10: 9 | B10: NOS d.o.o. | C10: nos.hr | D10: Zagreb | E10: Digital-transformation consultancy + AI-agent studio | F10: ERP/CRM/WMS/webshop projects plus its own AI agents (DokAgent, IOS Agent, MarketPulseAI); clients include Polleo, Eurotrade, Instar | G10: unknown | H10: AI agents that extract invoices into ERP and email customer statements (nos.hr (https://www.nos.hr/ai-agenti-za-pametnu-automatizaciju-poslovanja/)); OpenAI Partner Network | I10: Run their agents on one engine with guardrails, approvals and 190+ connectors | J10: 3/0/2/1/1 | K10: 7 | L10: DokAgent and IOS Agent already push documents into ERPs. ByteChef could run them on one self-hosted engine with guardrails and approval steps, without per-run pricing. | N10: =COUNTIF(Contacts!$B:$B,B10) -> 0
A11: 10 | B11: Nimium | C11: nimium.hr | D11: Zagreb | E11: Red Hat Premier partner, open-source infrastructure | F11: RHEL, OpenShift, Ansible and middleware since 2002; exclusive HR partner for Docker, EDB, Bacula, Zimbra | G11: 12–13; €2.48M revenue (CompanyWall (https://www.companywall.hr/tvrtka/nimium-doo/MMxvVxf0)) | H11: Ansible automation and "system integration and middleware deployment" for HT, PBZ and the Ministry of Finance (nimium.hr (https://www.nimium.hr/en/)) | I11: Business-workflow and AI-agent layer on their OpenShift/EDB stack | J11: 2/2/2/1/0 | K11: 7 | L11: You've brought Red Hat open source to HT and PBZ since 2003. ByteChef is the business-workflow and AI-agent layer that runs on the same OpenShift, fully self-hosted. | N11: =COUNTIF(Contacts!$B:$B,B11) -> 0
A12: 11 | B12: Netgen | C12: netgen.io | D12: Zagreb / Osijek / Zurich | E12: Open-source web and e-commerce agency (Symfony/Ibexa/Sylius) | F12: Complex digital and e-commerce builds since 2002; publishes its own open-source stack | G12: 40+ (Ibexa (https://www.ibexa.co/partners/netgen-switzerland-ag)) | H12: ERP and CMS integration projects; dedicated AI developers (careers (https://netgen.io/team-careers)) | I12: Open-source culture; ERP/PIM-to-shop sync | J12: 2/2/2/1/0 | K12: 7 | L12: Netgen already open-sources its Ibexa stack. ByteChef is an open-source, self-hostable engine for the ERP and AI-agent glue around your e-commerce builds, with no per-task pricing. | M12: Ivo Lukač (Co-founder); Igor Vrdoljak (Co-founder) | N12: =COUNTIF(Contacts!$B:$B,B12) -> 2
A13: 12 | B13: Solvership (formerly Poslovna inteligencija) | C13: solvership.com | D13: Zagreb | E13: Data, analytics and AI consultancy | F13: Data integration, migration, MDM, BI and AI for telco, banking and retail; 8 European offices | G13: about 187 (LinkedIn (https://hr.linkedin.com/company/poslovna-inteligencija)) | H13: Data-integration and migration practice; posts on "agentic AI readiness" (LinkedIn (https://hr.linkedin.com/company/poslovna-inteligencija), Netokracija (https://www.netokracija.com/poslovna-inteligencija-solvership-228397)) | I13: Agentic layer on their data platforms, self-hosted for bank and telco clients | J13: 2/0/2/2/1 | K13: 7 | L13: You're telling clients AI is only as ready as their data. ByteChef runs agentic workflows on that data inside the client's own VPC, with guardrails and human approvals, and no per-task cost. | M13: Lidija Karaga (President of the Board) | N13: =COUNTIF(Contacts!$B:$B,B13) -> 1
A14: 13 | B14: Q agency | C14: q.agency | D14: Zagreb | E14: Software/AI consultancy | F14: Engineering firm whose AI line covers custom agents and workflow automation | G14: 300+ (q.agency (https://q.agency/)) | H14: "AI and Data: custom agents, workflow automation, data integration"; "Human-Agent Pods"; an AI-architect ad weighs "n8n vs code-native" orchestration (Jooble (https://hr.jooble.org/desc/7847770379059401558)) | I14: Human-agent pods map onto ByteChef agents plus human-in-the-loop | J14: 2/0/1/2/1 | K14: 6 | L14: Your Human-Agent Pods need a production runtime. ByteChef is an open-source, self-hostable workflow and AI-agent platform with human-in-the-loop that Q could implement for clients with no licence to start. | M14: Filip Ljubić (Founder and CEO) | N14: =COUNTIF(Contacts!$B:$B,B14) -> 1
A15: 14 | B15: Devōt | C15: devot.team | D15: Zagreb / Osijek | E15: Software/AI dev shop | F15: Custom software (FinTech/HealthTech) with an AI-first practice | G15: 50–249 | H15: "Intelligent automation systems", "custom AI agents & workflows"; stack is Java + Spring Boot and Ollama (AI services (https://devot.team/services/ai-development)) | I15: Spring plus local-LLM interest fits self-hosted ByteChef | J15: 2/1/1/1/1 | K15: 6 | L15: Your team already ships Spring Boot services and Ollama-based agents. ByteChef is a Spring-based, open-source workflow and agent platform Devōt can self-host for clients and extend with custom components. | M15: Martin Morava (Founder and CEO); Rino Kovačević (Lead AI Engineer) | N15: =COUNTIF(Contacts!$B:$B,B15) -> 2
A16: 15 | B16: Neuralab | C16: neuralab.net | D16: Zagreb / New York | E16: Digital/e-commerce agency | F16: WooCommerce Platinum partner adding AI workflows; ISO 27001 | G16: about 16 | H16: "Claude-powered systems for content, operations and internal workflows"; OpenAI Select and Claude partner (home (https://www.neuralab.net/)) | I16: Open-source ecosystem (WordPress/Woo); store-ops and agent automation | J16: 2/1/2/0/1 | K16: 6 | L16: You're wiring Claude into WooCommerce operations. ByteChef gives Neuralab an open-source, self-hosted automation and agent platform to productise those workflows across your store clients with unmetered execution. | M16: Krešimir Končić (Founder and CEO) | N16: =COUNTIF(Contacts!$B:$B,B16) -> 1
A17: 16 | B17: LM Komunikacije | C17: lmkomunikacije.com | D17: Čakovec | E17: Automation / marketing agency | F17: Former creative agency, now automation and digital systems for B2B | G17: unknown; 200+ B2B clients | H17: Make.com process automation, CRM integration, Claude and AWS Lambda; clients include Maistra, the Ministry of Health and Hrvatska Lutrija (site (https://lmkomunikacije.com/)) | I17: Moves a Make-based practice to a self-hosted platform they control | J17: 2/0/2/1/1 | K17: 6 | L17: You build Make.com and CRM automations for 200+ B2B clients like Maistra. ByteChef lets LM Komunikacije run that work self-hosted with unmetered executions and AI agents, open source so there's no licence to start. | N17: =COUNTIF(Contacts!$B:$B,B17) -> 0
A18: 17 | B18: Uvid | C18: uviddigital.hr | D18: Zagreb / Ivanić-Grad | E18: Odoo Silver partner + BI | F18: Industry-specific Odoo (with Fiskalizacija 2.0) for manufacturers; ISO 9001/27001 | G18: 11–50 (LinkedIn (https://hr.linkedin.com/company/uvid-d.o.o.)) | H18: 200+ ERP/BI projects; 25 Odoo references (uviddigital.hr (https://uviddigital.hr/)) | I18: On-prem Odoo-to-MES, e-invoicing and BI flows for ISO 27001 manufacturers | J18: 2/1/2/1/0 | K18: 6 | L18: With 200+ Odoo/BI projects and ISO 27001, Uvid could offer manufacturers self-hosted ByteChef for Odoo↔MES and e-invoicing flows plus AI agents, without per-task fees. | N18: =COUNTIF(Contacts!$B:$B,B18) -> 0
A19: 18 | B19: E-Sustavi | C19: e-sustavi.hr | D19: Zagreb | E19: Odoo Gold partner (first in HR) | F19: Odoo/Luceed ERP for SMEs, ERP-integrated webshops, hosting | G19: about 10 | H19: 102 Odoo references (Odoo (https://www.odoo.com/partners/e-sustavi-doo-1462710)); builds e-shops integrated with Luceed/Odoo and hosts them (e-sustavi.hr (https://www.e-sustavi.hr/poslovna-rjesenja/odoo/)) | I19: Largest Odoo customer base in Croatia, and already a host, so it could resell hosted ByteChef | J19: 2/1/2/1/0 | K19: 6 | L19: 102 Odoo clients and your own hosting make you the natural home for self-hosted ByteChef, which connects Odoo and e-shops to everything else, with AI agents and no per-task pricing. | M19: Mario Marinić (Authorised representative) | N19: =COUNTIF(Contacts!$B:$B,B19) -> 1
A20: 19 | B20: Ecodica | C20: ecodica.eu | D20: Zagreb | E20: Odoo Silver partner (OCA-based) + MES | F20: Odoo ERP and MES/Industry 4.0 for manufacturing, engineering and shipbuilding | G20: unknown; 50+ projects (ecodica.eu (https://www.ecodica.eu/)) | H20: IoT/MES-to-ERP integrations on OCA community Odoo; public Odoo fork (GitHub (https://github.com/ecodica/odoo)) | I20: Community, self-hosted culture; IoT-to-MES-to-ERP pipelines | J20: 2/2/2/0/0 | K20: 6 | L20: You build on OCA community Odoo and wire IoT/MES into it. ByteChef is the open-source, self-hosted workflow engine for those shop-floor integrations, with AI agents and no per-task cost. | N20: =COUNTIF(Contacts!$B:$B,B20) -> 0
A21: 20 | B21: Maven Mule | C21: mavenmule.com | D21: Zagreb | E21: Salesforce consultancy + ISV (document automation) | F21: Salesforce implementation and integration plus its own document and CLM products | G21: about 29–32 (ZoomInfo (https://www.zoominfo.com/c/maven-mule/450675461)) | H21: "Integration Services: data integration and intelligent automation"; clients include VodafoneZiggo, Deutsche Bank, Knauf (mavenmule.com (https://www.mavenmule.com/)) | I21: Self-hostable integration option for mid-market Salesforce clients priced out of MuleSoft | J21: 3/0/2/1/0 | K21: 6 | L21: For clients who don't need MuleSoft pricing, ByteChef gives you an open-source, self-hosted integration and AI-agent engine to sit beside Salesforce, unmetered. | M21: Dragan Vujnović (CEO and Technical Architect); Ivan Tadić (CTO) | N21: =COUNTIF(Contacts!$B:$B,B21) -> 2
A22: 21 | B22: Sysbee (Plus Hosting Grupa) | C22: sysbee.net | D22: Pula | E22: Managed cloud / DevOps (AWS Select) | F22: Managed infrastructure, containers/Kubernetes and open-source monitoring for SMEs | G22: unknown (DHH group) (about (https://www.sysbee.net/about/)) | H22: Kubernetes DevOps suite (devops (https://www.sysbee.net/devops-services/)); little integration-practice evidence | I22: Managed-hosting channel: "ByteChef hosted in Croatia" for SMEs that want self-hosting without the ops | J22: 1/2/2/1/0 | K22: 6 | L22: Your SME clients want self-hosted n8n/Zapier alternatives but not the ops work. A managed ByteChef on Sysbee's Kubernetes stack would be an open-source, unmetered offer. | M22: Veljko Drakulić (Board member) | N22: =COUNTIF(Contacts!$B:$B,B22) -> 1
A23: 22 | B23: Lauris | C23: lauris.com | D23: Kastav | E23: HubSpot partner (+ hospitality tech) | F23: Says it is Croatia's largest HubSpot partner (Diamond) | G23: unknown | H23: Sales/marketing automation; custom integrations (Opera Cloud–HubSpot, Aircall–HubSpot, booking–loyalty) (integrations (https://www.lauris.com/integrations-migrations)); clients include BlueSun and Sunčani Hvar | I23: A self-hosted integration layer for hospitality PMS/booking/CRM flows | J23: 2/0/2/1/0 | K23: 5 | L23: Your Opera Cloud–HubSpot integration is exactly the kind of flow ByteChef runs. Partner with us to deliver self-hosted, unmetered hotel automations, open source so there's no licence to start. | M23: Luka Šimić (role unknown) | N23: =COUNTIF(Contacts!$B:$B,B23) -> 1
A24: 23 | B24: Ingemark | C24: ingemark.com | D24: Zagreb | E24: Enterprise software engineering | F24: Senior engineering for enterprise integration, AI and DevSecOps | G24: 50–76 | H24: Java/Spring "integration components" (job ad (https://ingemark.talentlyft.com/jobs/senior-java-developer-mf-jNS)). Has its own AssistCraft multi-agent platform, which overlaps | I24: Spring integration DNA; a workflow layer beside AssistCraft | J24: 2/0/1/1/1 | K24: 5 | L24: Your Java teams already build Spring integration components for SEE enterprises. ByteChef is a Spring-based, open-source workflow platform Ingemark could deploy self-hosted under those integrations, with no licence to start. | M24: Viktor Matić (Co-founder) | N24: =COUNTIF(Contacts!$B:$B,B24) -> 1
A25: 24 | B25: EXCEED Solutions | C25: exceed.hr | D25: Zagreb | E25: Microsoft Power Platform boutique | F25: Power BI, Fabric, Power Apps and Power Automate consultancy and training | G25: 5 named core team | H25: Power Automate solutions; 90+ clients and 150+ projects incl. Samsung, Bosch, Intesa Sanpaolo (about (https://exceed.hr/en/about/)) | I25: An option for clients outside Microsoft licensing or needing on-prem, unmetered flows | J25: 2/0/2/1/0 | K25: 5 | L25: You've delivered 150+ Power Platform projects. ByteChef gives EXCEED a self-hosted, open-source automation option for clients who want flows without per-user Power Automate licensing. | M25: Krešimir Ledinski (Fabric Architect / MCT) | N25: =COUNTIF(Contacts!$B:$B,B25) -> 1
A26: 25 | B26: DignetSoftware | C26: dignet.hr | D26: Zagreb | E26: Microsoft Dynamics BC / LS Central partner | F26: Business Central, LS Central retail and Dynamicweb e-commerce; BC localisation for 5 Adriatic countries | G26: about 25 | H26: BC-to-Shopify integration, Dynamics integrations and e-invoicing modules (about (https://www.dignet.hr/en/about-us)) | I26: Retail/e-commerce integrations around BC that Power Automate handles poorly or that must run on-prem | J26: 2/0/2/1/0 | K26: 5 | L26: You already build BC↔Shopify and e-invoicing links. ByteChef could carry the other 190+ connectors and AI agents for your retail clients, self-hosted and unmetered. | N26: =COUNTIF(Contacts!$B:$B,B26) -> 0
A27: 26 | B27: 2P | C27: 2p.hr | D27: Osijek | E27: Odoo Silver partner | F27: Odoo for finance, sales, procurement and manufacturing | G27: unknown; 16 references (Odoo (https://www.odoo.com/partners/2p-d-o-o-14066453)) | H27: ERP implementations for Byte-lab, Hell Energy Adria and MARBLE; no explicit integration practice | I27: Eastern-Croatia Odoo channel | J27: 1/1/2/0/0 | K27: 4 | L27: Your Odoo clients like Hell Energy Adria will need Odoo talking to other systems. ByteChef gives 2P an open-source, self-hostable way to sell that, with no per-task fees. | N27: =COUNTIF(Contacts!$B:$B,B27) -> 0
A28: 27 | B28: LeverUP | C28: leverup consulting | D28: Zagreb | E28: Salesforce / Braze / Adobe martech consultancy | F28: Marketing Cloud, Braze and Adobe implementations | G28: 11–50 (LinkedIn (https://hr.linkedin.com/company/leverup-consulting)) | H28: Marketing-automation implementations | I28: Data-sync and AI-agent workflows feeding martech stacks | J28: 2/0/1/1/0 | K28: 4 | L28: MarTech journeys break where data has to move between systems. ByteChef is an open-source, self-hosted engine with AI agents to feed Braze and Marketing Cloud, unmetered. | M28: Daria Nemčonok (CEO and co-founder) | N28: =COUNTIF(Contacts!$B:$B,B28) -> 1

Sheet Contacts
A1: type | B1: company | C1: name | D1: role | E1: linkedin | F1: status | G1: notes
A2: buyer | B2: Aircash | C2: Hrvoje Ćosić | D2: Director / CEO | E2: https://www.linkedin.com/in/hrvoje-cosic-b4b6b438/
A3: buyer | B3: Aircash | C3: Branimir Petrušić | D3: Director of Product (one source says CTO; unverified)
A4: buyer | B4: Aircash | C4: Ivana Arambašić | D4: Head of IT Operations (as of 2022)
A5: buyer | B5: HBOR | C5: Hrvoje Čuvalo | D5: President of the Board (IT sector director not named publicly)
A6: buyer | B6: Hypefy | C6: Stjepan Zelić | D6: Co-founder and CEO
A7: buyer | B7: PREMIS | C7: Toni Premeru / Branko-Silvio Premeru | D7: Owner / Director (sources differ)
A8: buyer | B8: KentBank | C8: Hasan Ecesoy | D8: President of the Board; owns the IT and digital-transformation sectors
A9: buyer | B9: JANAF | C9: Stjepan Adanić | D9: President of the Board
A10: buyer | B10: AGRIVI | C10: Guillaume Rabhi | D10: Chief Digital Officer (the AI & Automation role reports to him)
A11: buyer | B11: AGRIVI | C11: Matija Žulj | D11: Founder and CEO | E11: https://www.linkedin.com/in/matijazulj/
A12: buyer | B12: Monri Payments | C12: Damir Čaušević | D12: CEO
A13: buyer | B13: Zagrebačka burza (ZSE) | C13: Ivana Gažić | D13: President of the Board
