Workbook

Sheet Targets
A1: company | B1: url | C1: country | D1: segment | E1: sub_segment | F1: category | G1: description | H1: stage_funding | I1: est_size | J1: pain_evidence | K1: score_breakdown | L1: score | M1: wave | N1: owner | O1: first_line | P1: research_hook | Q1: verify_before_sending | R1: contacts | S1: n_contacts | T1: contact_email | U1: touch1_date | V1: followup_date | W1: breakup_date | X1: replied | Y1: call_booked | Z1: call_held | AA1: partner_status | AB1: notes
A2: EXAMPLE - Acme SaaS | B2: acme.example | C2: Germany | D2: EU vertical | F2: Vertical SaaS | L2: 9 | M2: 1 | N2: Ivica | O2: Example hook referencing their specific evidence. | Q2: Example caveat to check first | R2: Jane Doe (CTO) | S2: =COUNTIF(Contacts!$A:$A,A2) -> 0 | T2: jane@acme.example | U2: 2026-08-04 | V2: 2026-08-08 | W2: 2026-08-14 | X2: Y | Y2: 2026-08-11 | Z2: 2026-08-12 | AA2: discovery call held | AB2: asked about SOC2; send follow-up deck
A3: Attio | B3: attio.com | C3: UK | D3: Dev tools | F3: Sales/CRM | G3: AI-native CRM for GTM teams | H3: Series B $52M GV, Aug 2025 (blog (https://attio.com/blog/attio-raises-52m-series-b)) | I3: ~84 (Tracxn (https://tracxn.com/d/companies/attio/__zXaorGoGUFFCntq5i6GuYbFjA5y0l4NPgP5t1R3FhXg)) | J3: G2: native library ~8 apps vs HubSpot 1,500+; "Some more native integrations would be good so I don't have to use Zapier" (G2 (https://www.g2.com/products/attio/reviews?qs=pros-and-cons)); /apps 403 | K3: 2/2/3/2/1 | L3: 10 | M3: 1 | N3: Ivica | O3: Your G2 reviews' most consistent complaint is the native-integration gap versus HubSpot's 1500-app marketplace - close it white-label. | P3: Your G2 reviews' most consistent complaint is the native-integration gap versus HubSpot's 1,500-app marketplace - we build an open-source embedded iPaaS that lets an 84-person team close that gap white-label instead of hand-coding each connector. | Q3: Apps page 403 during research | S3: =COUNTIF(Contacts!$A:$A,A3) -> 0
A4: folk | B4: folk.app | C4: France | D4: Dev tools | F4: Sales/CRM | G4: Lightweight CRM for agencies/founders | H4: Series A $33M Bessemer per aggregators (PitchBook (https://pitchbook.com/profiles/company/228251-62)) - primary not fetched | I4: 20–55 (getlatka (https://getlatka.com/companies/folk.app/team)) | J4: Native integrations limited to Gmail/Outlook/LinkedIn/WhatsApp; "4,900+ integrations" are via Zapier/Make; G2/Capterra flag limited native integrations, no Salesforce sync (capsulecrm review (https://capsulecrm.com/blog/folk-crm-alternatives/), G2 (https://www.g2.com/products/folk-folk/reviews?qs=pros-and-cons)) | K4: 2/2/3/2/1 | L4: 10 | M4: 1 | N4: Ivica | O4: Reviewers keep dinging folk for four native integrations and pushing the rest through customers' paid Zapier plans - ship the Salesforce/HubSpot syncs they ask for. | P4: Reviewers keep dinging folk for having only four native integrations and pushing everything else through your customers' paid Zapier plans - an embedded open-source iPaaS could let you ship the Salesforce/HubSpot syncs they're asking for without staffing a connector team. | Q4: Funding figure via aggregators - verify | S4: =COUNTIF(Contacts!$A:$A,A4) -> 0
A5: Cargoson | B5: cargoson.com | C5: Estonia | D5: EU vertical | F5: Logistics (TMS) | G5: Cloud TMS consolidating carrier booking/rates/tracking | H5: Bootstrapped (Getlatka (https://getlatka.com/companies/cargoson.com)) | I5: ~13 emp (Getlatka (https://getlatka.com/companies/cargoson.com)) | J5: Core product = integration surface: 2,000+ carrier integrations + ERP connectors maintained by ~13 people (cargoson.com (https://www.cargoson.com/en)); /integrations 403 | K5: 2/2/3/2/1 | L5: 10 | M5: 1 | N5: Co-founder | O5: A 13-person team maintaining 2000+ carrier and ERP connectors - we build the embedded engine that ships connectors without hand-coding each one. | P5: Noticed your 13-person team maintains 2,000+ carrier and ERP connectors - we build the embedded integration engine that lets teams like yours ship new connectors without hand-coding each one. | Q5: Integrations page 403 during research | S5: =COUNTIF(Contacts!$A:$A,A5) -> 0
A6: Vertuoza | B6: vertuoza.com | C6: Belgium | D6: EU vertical | F6: Construction | G6: Quote-to-invoice SaaS for SMB contractors (BE/FR/LU/CH) | H6: Series A €10M, 2023 (Fortino (https://www.fortino.vc/news/vertuoza-reinforces-its-growth-ambitions-and-successfully-concludes-its-10-million-eu-series)) | I6: ~110–123 (LeadIQ (https://leadiq.com/c/vertuoza/601737cf411f372b409a11b2)) | J6: Outsourced accounting integrations to Chift (case study (https://www.chift.eu/case-studies/how-vertuoza-unlocked-accounting-automation-with-chifts-integrations)); review notes limited native integrations, no public API/Zapier (Skello (https://www.skello.io/blog/avis-vertuoza-alternatives)) | K6: 2/2/3/2/1 | L6: 10 | M6: 1 | N6: Co-founder | O6: You solved accounting sync via Chift's unified API - get the same self-serve depth across banking, suppliers and ERP under your own brand. | P6: Saw you solved accounting sync via Chift's unified API - an embedded iPaaS would let you offer the same self-serve depth across banking, suppliers and ERP connectors beyond accounting, under your own brand. | S6: =COUNTIF(Contacts!$A:$A,A6) -> 0
A7: Humaans | B7: humaans.io | C7: UK | D7: HR/fin-ops | F7: HRIS | G7: API-first employee-data hub / HRIS for fast-growing SMBs | H7: Series A $15M, Oct 2022 (TechCrunch (https://techcrunch.com/2022/10/04/humaans-raises-15m-to-simplify-hr-tasks-like-onboarding/)) | I7: ~34–53 emp (Latka (https://getlatka.com/companies/humaans.io), PitchBook (https://pitchbook.com/profiles/company/442747-00)) | J7: Reviewers: "integration support is minimal, few built-in connectors", Lattice sync is one-way, users requesting Deel integration (Research.com (https://research.com/software/reviews/humaans), SoftwareFinder (https://softwarefinder.com/hr/humaans/reviews)) | L7: 10 | M7: 1 | N7: Ivica | O7: Reviewers call integration support 'minimal' and ask for Deel plus true two-way Lattice sync - exactly the long tail an embedded iPaaS closes without a connectors team. | P7: Your G2 reviewers love Humaans but call integration support 'minimal' and are asking for Deel and true two-way Lattice sync - that's exactly the long tail an embedded iPaaS closes without hiring a connectors team. | Q7: Re-verify review quotes on G2/Capterra; UK counted for EU bonus | S7: =COUNTIF(Contacts!$A:$A,A7) -> 0
A8: Kenjo | B8: kenjo.io | C8: Germany | D8: HR/fin-ops | F8: HRIS (frontline/SMB) | G8: All-in-one HR for frontline & SMB workforces (DE/ES/LatAm) | H8: Series A €8.8M, Sep 2023 (Tech.eu (https://tech.eu/2023/09/18/berlin-based-kenjo-8-8m-hrtech-to-latin-america/)) | I8: ~71–98 emp (Tracxn (https://tracxn.com/d/companies/kenjo/__V7FbYPAoSJt0jRXHCCyaW3ciVaB5yeoJmRr7d7o_ao8), PitchBook (https://pitchbook.com/profiles/company/92904-13)) | J8: "Integration with third-party software is limited"; 3.8/5 on integrations; payroll depends on DATEV/third-party connections; users asking deeper Slack integration (Research.com (https://research.com/software/reviews/kenjo), rfp.wiki (https://www.rfp.wiki/hr-office/hcm-suites-1000-employee-enterprises/hris-systems/kenjo), Capterra (https://capterra.com/p/165837/kenjo/reviews/)) | L8: 10 | M8: 1 | N8: Ivica | O8: Payroll runs through DATEV bridges yet reviewers rate integrations 3.8/5 - ship the Slack/payroll connectors users keep asking for. | P8: Kenjo's payroll story runs through DATEV and partner connections, yet reviewers still rate your third-party integrations 3.8/5 - an embedded integration layer would let you ship the Slack/payroll connectors users keep asking for. | S8: =COUNTIF(Contacts!$A:$A,A8) -> 0
A9: Cal.com | B9: cal.com | C9: USA | D9: Dev tools | F9: Dev tools / scheduling | G9: Open-source scheduling infrastructure | H9: Series A $25M, 2022 (VentureBeat (https://venturebeat.com/business/open-source-calendly-rival-cal-com-raises-25m)) | I9: ~44 (Tracxn (https://tracxn.com/d/companies/calcom/__IEeuL9zwIQRcTDpJAAntiwKZ0CItPOOlE9FD_QgbF4o)) | J9: 43 open "integration" issues across org; Zoho Meeting request calls Zapier workaround "cumbersome and error-prone" (#19305 (https://github.com/calcom/cal.diy/issues/19305)) | K9: 2/2/3/2/0 | L9: 9 | M9: 1 | N9: Ivica | O9: There are 43 open integration requests across your GitHub org, with users calling the Zapier workaround 'cumbersome and error-prone'. | P9: There are 43 open integration requests across your GitHub org, with users calling the Zapier workaround 'cumbersome and error-prone' - open-source to open-source, ByteChef could power those long-tail app-store connectors so your core team stays on scheduling. | S9: =COUNTIF(Contacts!$A:$A,A9) -> 0
A10: Chatwoot | B10: chatwoot.com | C10: USA | D10: Dev tools | F10: Customer support | G10: Open-source omnichannel support platform | H10: Seed $1.6M, YC W21 (Tracxn (https://tracxn.com/d/companies/chatwoot/__aRgDQ9vdvJArJxEw66gaFsL2oc8vTbzfUwPrEf6mpIo)) | I10: 10–12 (YC (https://www.ycombinator.com/companies/chatwoot)) | J10: Discord integration open since 2021, 34 reactions (#1941 (https://github.com/chatwoot/chatwoot/issues/1941)); MS Teams since 2021 (#1655 (https://github.com/chatwoot/chatwoot/issues/1655)); HubSpot since 2020 (#1197 (https://github.com/chatwoot/chatwoot/issues/1197)) | K10: 2/2/3/2/0 | L10: 9 | M10: 1 | N10: Ivica | O10: Your Discord, Teams and HubSpot integration issues have been open 4-5 years with dozens of upvotes - open-source to open-source, clear the backlog. | P10: Your Discord, Teams, and HubSpot integration issues have been open for 4-5 years with dozens of upvotes - as a fellow open-source company we'd love to show how embedding ByteChef could clear that backlog without growing your 12-person team. | S10: =COUNTIF(Contacts!$A:$A,A10) -> 0
A11: ilert | B11: ilert.com | C11: Germany | D11: Dev tools | F11: Incident management | G11: AI-first incident management / on-call | H11: Bootstrapped, ~$1.4M ARR (getlatka (https://getlatka.com/companies/ilert.com)) | I11: ~13 (getlatka (https://getlatka.com/companies/ilert.com)) | J11: Changelog shows team hand-shipping integrations monthly (Dynatrace, Raygun) (changelog (https://docs.ilert.com/changelog)) | K11: 2/2/2/2/1 | L11: 9 | M11: 1 | N11: Ivica | O11: A 13-person bootstrapped team hand-building Dynatrace and Raygun integrations monthly - match PagerDuty's catalog without PagerDuty's headcount. | P11: Your changelog shows a 13-person bootstrapped team hand-building Dynatrace and Raygun integrations month after month - embedding an open-source iPaaS could let ilert match PagerDuty's catalog without PagerDuty's headcount. | S11: =COUNTIF(Contacts!$A:$A,A11) -> 0
A12: Twenty | B12: twenty.com | C12: France | D12: Dev tools | F12: Sales/CRM | G12: Open-source CRM (Salesforce alt), YC S23 | H12: Series A $38M Nov 2025 (Tracxn (https://tracxn.com/d/companies/twenty/__oyf_sCMiigApXb-QCd9gzMXlCdKb6Za7OSNrSEGQJ7E)) | I12: unknown | J12: Users: missing PostHog integration "is one of the issues blocking leaving HubSpot" (Discussion #16735 (https://github.com/twentyhq/twenty/discussions/16735)) | K12: 2/1/3/2/1 | L12: 9 | M12: 1 | N12: Ivica | O12: In your Native Integrations discussion, users say the missing PostHog connector blocks leaving HubSpot - ship that long tail inside Twenty. | P12: In your Native Integrations discussion, users say the missing PostHog connector is literally what blocks them from leaving HubSpot - ByteChef is an open-source embedded iPaaS (AGPL-friendly, self-hostable) that could ship that long tail inside Twenty. | Q12: Headcount unknown | S12: =COUNTIF(Contacts!$A:$A,A12) -> 0
A13: Doctorly | B13: doctorly.de | C13: Germany | D13: EU vertical | F13: Health (PVS) | G13: Cloud practice management for German medical practices | H13: Series A $17.2M total (Tech.eu (https://tech.eu/2023/03/01/berlin-based-health-tech-startup-doctorly-diagnoses-10-million/), Silicon Canals (https://siliconcanals.com/doctorly-raises-6-7m/)) | I13: ~58 (ZoomInfo (https://www.zoominfo.com/c/doctorly-gmbh/507136489)) | J13: Heavy regulated integration load (TI, GDT/DICOM); positions "integration platform for wider health industry" as product (The SaaS News (https://www.thesaasnews.com/news/doctorly-raises-10-million-in-series-a)) | K13: 2/2/2/2/1 | L13: 9 | M13: 1 | N13: Co-founder | O13: You describe doctorly as including an integration platform for the wider health industry - we provide exactly that layer, open-source and embeddable. | P13: You've described doctorly as including an integration platform for the wider health industry - we provide exactly that layer (open-source, embeddable) so your ~60-person team doesn't have to build connector infrastructure from scratch. | S13: =COUNTIF(Contacts!$A:$A,A13) -> 0
A14: Nelly | B14: getnelly.de | C14: Germany | D14: EU vertical | F14: Health (practice fintech) | G14: Financial OS for medical/dental practices | H14: Series B €50M, Jan 2025 (Tech.eu (https://tech.eu/2025/01/15/berlin-s-nelly-raises-50m-series-b-to-free-medical-practices-from-tedious-bureaucracy/)) | I14: unknown (1,200+ practices) | J14: Built own "Nelly Connector" to bridge into "any practice software" - per-PVS plumbing maintained in-house (Connector (https://www.getnelly.de/en/software-solutions/connector), partners (https://www.getnelly.de/en/partners)) | K14: 2/1/3/2/1 | L14: 9 | M14: 1 | N14: Co-founder | O14: The Nelly Connector speaks to every German PVS one interface at a time - turn that connector backlog into configuration instead of engineering. | P14: Your Nelly Connector has to speak to every German PVS one interface at a time - an embedded integration platform could turn that connector backlog into configuration instead of engineering. | Q14: Headcount unknown | S14: =COUNTIF(Contacts!$A:$A,A14) -> 0
A15: Payaca | B15: payaca.com | C15: UK | D15: EU vertical | F15: Field service (clean-tech trades) | G15: CRM/job management for solar & heat-pump installers | H15: Seed £331k Blackfinch 2021 (PE Wire (https://www.privateequitywire.co.uk/payaca-secures-gbp331k-investment-blackfinch/)) | I15: unknown (small) | J15: Four native connectors (QuickBooks, Xero, OpenSolar, Heatpunk), rest via Zapier (integrations (https://payaca.com/us/features/integrations)); 403, from indexed copy | K15: 2/1/3/2/1 | L15: 9 | M15: 1 | N15: Co-founder | O15: Four native connectors and Zapier for the rest - ship white-label native integrations (MCS bodies, suppliers, accounting) without per-connector engineering. | P15: Your integrations page lists four native connectors and leans on Zapier for the rest - we help vertical SaaS teams ship white-label native integrations (MCS bodies, suppliers, accounting) without per-connector engineering. | Q15: Size unverified; last disclosed round stale | S15: =COUNTIF(Contacts!$A:$A,A15) -> 0
A16: Plancraft | B16: plancraft.com | C16: Germany | D16: EU vertical | F16: Construction (trades) | G16: Cloud software for craft businesses; 20k+ customers | H16: Series B €38M, Aug 2025 (EU-Startups (https://www.eu-startups.com/2025/08/e38-million-for-german-saas-startup-plancraft-to-lead-ai-transformation-in-european-construction/)) | I16: ~117–141 (Getlatka (https://getlatka.com/companies/plancraft.com)) | J16: Integration story file-based: DATEV via CSV, otherwise GAEB/DATANORM exchange formats (Schnittstellen (https://plancraft.com/de-de/funktionen/software-schnittstellen)) | K16: 2/2/2/2/1 | L16: 9 | M16: 1 | N16: Co-founder | O16: Your DATEV workflow still runs on CSV export/import while you scale to 11 countries - get real two-way accounting and supplier APIs. | P16: Your DATEV workflow is still CSV export/import - as you scale across 11 countries, an embedded integration platform gets you real two-way accounting and supplier APIs without growing an integrations team. | R16: Julian Wiedenhaus (CEO & Co-founder) | S16: =COUNTIF(Contacts!$A:$A,A16) -> 1
A17: Atlar | B17: atlar.com | C17: Sweden | D17: HR/fin-ops | F17: Treasury / fin-ops | G17: Treasury & payments platform on direct bank connectivity | H17: Seed €5M, Nov 2022; $13.5M total (FinSMEs (https://www.finsmes.com/2022/11/atlar-raises-e5m-in-seed-funding.html), Atlar (https://www.atlar.com/company)) | I17: unknown (seed-to-A scale) | J17: Dedicated "Connectivity" team of 7 engineers growing to 9 that "builds and operates the integrations that connect Atlar to the world's banks"; hiring an EM for it (Atlar careers (https://careers.atlar.com/jobs/7898497-engineering-manager-connectivity)) | L17: 9 | M17: 1 | N17: Ivica | O17: You are staffing a nine-engineer Connectivity team for bank/ERP integrations - worth comparing what an embedded open-source layer takes off that roadmap. | P17: You're staffing a nine-engineer Connectivity team just to keep bank and ERP integrations alive - worth comparing what an embedded, open-source integration layer could take off that roadmap. | Q17: Headcount unknown | R17: Johannes Elgh (CTO & Co-founder) | S17: =COUNTIF(Contacts!$A:$A,A17) -> 1
A18: Hyperline | B18: hyperline.co | C18: France | D18: HR/fin-ops | F18: Billing / revenue | G18: SMB-focused billing & subscription platform | H18: Seed ~$14M total (incl. $10M ext, Jan 2025) (Tech.eu (https://tech.eu/2025/01/16/hyperline-raises-10m-for-automated-billing/)) | I18: unknown (seed scale) | J18: Changelog shows accounting/payment connectors shipped one at a time by the core team: Zoho Books (Mar 2026), Adyen (Apr 2026), Rillet + NetSuite (May 2026) (changelog (https://docs.hyperline.co/changelog/2026-03)); integrations page not verifiable (403) | L18: 9 | M18: 1 | N18: Ivica | O18: Your changelog shows accounting connectors shipped one at a time (Zoho Books in March, NetSuite/Rillet in May) - announce ten a quarter without burning core eng. | P18: Your changelog shows the team shipping accounting connectors one by one - Zoho Books in March, NetSuite and Rillet in May - an embedded iPaaS would let you announce ten of those a quarter without burning core eng cycles. | Q18: Headcount unknown; integrations page 403 during research | R18: Clément Garbay (Co-founder & CTO) | S18: =COUNTIF(Contacts!$A:$A,A18) -> 1
A19: Payslip | B19: payslip.com | C19: Ireland | D19: HR/fin-ops | F19: Global payroll control | G19: Vendor-agnostic global-payroll control layer over HCM + local payroll providers | H19: Series A ~€2.7M + $10M extension, 2020–21; growth financing May 2026 (PR Newswire (https://www.prnewswire.com/news-releases/payslip-adds-10m-to-its-series-a-financing-to-disrupt-traditional-service-model-for-global-payroll-301293783.html), PR Newswire 2026 (https://www.prnewswire.com/news-releases/payslip-secures-growth-financing-to-scale-ai-global-payroll-platform-302783394.html)) | I19: unknown (150-hire plan announced 2021, Silicon Canals (https://siliconcanals.com/payslip-raises-8-3m/)) | J19: Business model *is* connectors: in-house "Integrations as a Service specialists" hand-built the Workday PECI multi-country connector and SuccessFactors integrations (Payslip blog (https://payslip.com/resources/blog/fastest-payroll-integration-in-workday-history-yes-we-did), Payslip Connect (https://payslip.com/product/payslip-connect)) | L19: 9 | M19: 1 | N19: Ivica | O19: Your team hand-builds every HCM-to-payroll connector (Workday PECI, SuccessFactors) - the workload an embedded platform turns into configuration. | P19: Your team hand-builds every HCM-to-payroll connector - Workday PECI, SuccessFactors and beyond - which is precisely the workload an embedded integration platform turns from custom engineering into configuration. | Q19: Headcount unknown | R19: Fidelma McGuirk (Founder & CEO) | S19: =COUNTIF(Contacts!$A:$A,A19) -> 1
A20: Sequence | B20: sequencehq.com | C20: UK | D20: HR/fin-ops | F20: Billing / CPQ / AR | G20: AI billing, quoting and AR automation for B2B finance teams | H20: Series A $20M, Dec 2025; $38M total (PYMNTS (https://www.pymnts.com/news/investment-tracker/2025/sequence-raises-20-million-for-ai-powered-billing-automation/)) | I20: unknown (Series A scale) | J20: Only QuickBooks Online and Xero are native two-way accounting syncs; NetSuite handled via "NetSuite-compatible invoice exports" and "get in touch with our team" (docs - NetSuite (https://docs.sequencehq.com/integrations/netsuite), Xero (https://docs.sequencehq.com/integrations/xero)) | L20: 9 | M20: 1 | N20: Ivica | O20: Your docs route NetSuite customers to CSV exports and 'talk to our team' - make NetSuite and the next ten ERPs native. | P20: Your docs still route NetSuite customers to CSV invoice exports and a 'talk to our team' link - embedding a white-label integration layer would make NetSuite (and the next ten ERPs) native without a connectors squad. | Q20: Headcount unknown | R20: Riya Grover (Co-founder & CEO) | S20: =COUNTIF(Contacts!$A:$A,A20) -> 1
A21: Zelt | B21: zelt.app | C21: UK | D21: HR/fin-ops | F21: HR / payroll / IT ops | G21: All-in-one HR, payroll and device management for SMBs | H21: Seed $3.5M (2022) + $6M (Jan 2025), $13.2M total (EU-Startups (https://www.eu-startups.com/2025/01/hrtech-zelt-raises-e5-7-million-to-fix-people-operations-once-and-for-all/)) | I21: unknown (seed scale) | J21: Reviews flag "lack of a comprehensive integration ecosystem or a public API", syncing issues with Nest pensions, manual bank-file edits for payroll (hr.software (https://www.hr.software/reviews/zelt), Research.com (https://research.com/software/reviews/zelt)) | L21: 9 | M21: 1 | N21: Ivica | O21: Reviews flag the missing integration ecosystem and public API - an embedded iPaaS gives you both, plus fixes like the Nest pension sync. | P21: Reviewers praise Zelt's all-in-one scope but call out the missing integration ecosystem and public API - an embedded iPaaS would give you both, plus fixes for pain points like the Nest pension sync, in one move. | Q21: Headcount unknown | R21: Chris Priebe (Co-founder & CEO) | S21: =COUNTIF(Contacts!$A:$A,A21) -> 1
A22: Coperniq | B22: coperniq.io | C22: USA | D22: US vertical | F22: Energy/solar contractor software | G22: Workflow + CRM for solar/energy contractors (YC W23) | H22: Seed $4M, Nov 2023 (TechCrunch (https://techcrunch.com/2023/11/06/coperniq-seed-round/)) | J22: Support docs show ~8 native integrations, rest "mediated via Zapier" (support docs (https://support.coperniq.io/integrations/quickbooks-online-and-desktop-integration)); /integrations 403 | L22: 9 | M22: 1 | N22: Co-founder | O22: Your support docs list about eight native integrations with the rest routed through Zapier - ship the long tail natively and white-labeled. | P22: Your support docs list about eight native integrations with the rest routed through Zapier - ByteChef lets solar-software teams ship the long tail natively and white-labeled without burning sprint time. | Q22: Integrations page 403 during research | R22: Abdullah Al-Zandani (CEO) | S22: =COUNTIF(Contacts!$A:$A,A22) -> 1
A23: Latchel | B23: latchel.com | C23: USA | D23: US vertical | F23: Proptech - maintenance ops | G23: Maintenance ops + resident amenities for property managers (YC) | H23: Series A $16.7M, Jul 2022 (FinSMEs (https://www.finsmes.com/2022/07/latchel-raises-16-7m-in-series-a-funding.html)) | J23: Series A PR earmarks funds to "deepen third party property management integrations" (PR Newswire (https://www.prnewswire.com/news-releases/latchel-closes-16-7-million-to-enhance-resident-services-and-maintenance-workflow-301593940.html)) | L23: 9 | M23: 1 | N23: Co-founder | O23: Your Series A announcement earmarked funds to 'deepen third party property management integrations' - compress that roadmap from quarters to weeks. | P23: Your Series A announcement earmarked funds to 'deepen third party property management integrations' - that is exactly the roadmap an embedded iPaaS compresses from quarters to weeks. | R23: Ethan Lieber (CEO & Co-founder) | S23: =COUNTIF(Contacts!$A:$A,A23) -> 1
A24: Lawmatics | B24: lawmatics.com | C24: USA | D24: US vertical | F24: Legal - CRM/intake | G24: Legal CRM, intake, marketing automation for law firms | H24: Series A $10M, Dec 2021 (GlobeNewswire (https://www.globenewswire.com/news-release/2021/12/15/2353012/0/en/lawmatics-raises-10m-in-series-a-funding-to-change-the-way-lawyers-drive-business.html)) | J24: G2: "weak in billing, time tracking, document management, and integrations" (G2 (https://www.g2.com/products/lawmatics/reviews?qs=pros-and-cons)); Zapier as workaround (help center (https://help.lawmatics.com/en/articles/10699986-lawmatics-zapier-app-overview)) | L24: 9 | M24: 1 | N24: Co-founder | O24: G2 reviewers praise your automation but repeatedly flag integrations as a weak spot - close the gap without staffing a connector team. | P24: G2 reviewers praise Lawmatics' automation but repeatedly flag integrations as a weak spot - an embedded iPaaS would close that gap without you staffing a dedicated connector team. | R24: Matt Spiegel (Founder & CEO) | S24: =COUNTIF(Contacts!$A:$A,A24) -> 1
A25: Checkly | B25: checklyhq.com | C25: Germany | D25: Dev tools | F25: Observability | G25: Code-first synthetic monitoring | H25: Series B $20M Balderton Jul 2024 (blog (https://www.checklyhq.com/blog/announcing-20m-to-enable-engineers-to-detect-and-r/)) | I25: ~58 (Tracxn (https://tracxn.com/d/companies/checkly/__Tm43V0cikPcbX150mT8CmGxTOlmV1N5Fpmh-A6aB-V4)) | J25: Public-roadmap alert-channel requests (OpsGenie #18 (https://github.com/checkly/public-roadmap/issues/18)); modest channel set (docs (https://www.checklyhq.com/docs/communicate/alerts/channels/)); /integrations 403 | K25: 2/2/1/2/1 | L25: 8 | M25: 2 | N25: Ivica | O25: Your alert-channel list is a fraction of Datadog's and the community has filed integration requests for years - catalog breadth at startup cost. | P25: Checkly's alert-channel list is still a fraction of what Datadog offers and your community has been filing integration requests since the public-roadmap days - an embedded open-source iPaaS could give you their catalog breadth at Berlin-startup cost. | Q25: Feedback board and integrations page 403 during research | R25: Hannes Lenke (CEO) | S25: =COUNTIF(Contacts!$A:$A,A25) -> 1
A26: Infisical | B26: infisical.com | C26: USA | D26: Dev tools | F26: Security | G26: Open-source secrets/identity management | H26: Series A $16M Jun 2025 (PR Newswire (https://www.prnewswire.com/news-releases/infisical-secures-16m-series-a-to-redefine-enterprise-secrets-identity-and-access-management-302475063.html)) | I26: ~20–50 (Startup Intros (https://startupintros.com/orgs/infisical)) | J26: Native-sync bugs open for years: duplicate syncs since May 2023 (#611 (https://github.com/Infisical/infisical/issues/611)), GitLab masked-sync since Jun 2024 (#2035 (https://github.com/Infisical/infisical/issues/2035)) | K26: 2/2/2/2/0 | L26: 8 | M26: 2 | N26: Ivica | O26: Secret-sync bugs like the GitLab masked-sync failure sit open since 2024 across your hand-built connector fleet - we maintain 190+ so yours do not rot. | P26: Secret-sync integrations are core to Infisical, yet bugs like the GitLab masked-sync failure have sat open since 2024 across your hand-built connector fleet - a fellow open-source team, we maintain 190+ connectors so yours don't rot. | R26: Maidul Islam (Co-founder) | S26: =COUNTIF(Contacts!$A:$A,A26) -> 1
A27: Plane | B27: plane.so | C27: India/USA | D27: Dev tools | F27: Project management | G27: Top open-source PM tool (Jira alt) | H27: Seed $4M OSS Capital 2024 (blog (https://plane.so/blog/plane-raises-4m-seed)) | I27: unknown | J27: Gitea sync open since Jul 2023, 94 reactions (#1495 (https://github.com/makeplane/plane/issues/1495)); GitLab parity (#8088 (https://github.com/makeplane/plane/issues/8088)); Mattermost (#6001 (https://github.com/makeplane/plane/issues/6001)) | K27: 2/1/3/2/0 | L27: 8 | M27: 2 | N27: Ivica | O27: Your Gitea-sync issue has 94 upvotes since 2023 with GitLab parity and Mattermost queued behind it - power those syncs, keep engineers on core PM. | P27: Your Gitea-sync issue has 94 upvotes and has sat open since 2023 while GitLab parity and Mattermost wait behind it - as an open-source embedded iPaaS, ByteChef could power those syncs so your engineers stay on the core PM experience. | Q27: Headcount unknown | R27: Vamsi Kurama (CEO & Co-founder) | S27: =COUNTIF(Contacts!$A:$A,A27) -> 1
A28: Secoda | B28: secoda.co | C28: Canada | D28: Dev tools | F28: Data tools | G28: AI data search/catalog/lineage | H28: Series A $14M Craft 2023 (FinSMEs (https://www.finsmes.com/2023/09/secoda-raises-14m-in-series-a-funding.html)) | I28: ~19–22 (LeadIQ (https://leadiq.com/c/secoda/60d3333f47ed3badf9a78fdd)) | J28: Docs promise integrations "on the roadmap" (Airflow, S3, great_expectations), invite requests via Slack/email (docs (https://docs.secoda.co/integrations)) | K28: 2/2/2/2/0 | L28: 8 | M28: 2 | N28: Ivica | O28: Your docs promise Airflow, S3 and great_expectations connectors 'on the roadmap' and ask users to email requests - clear the whole queue. | P28: Your integrations docs promise Airflow, S3, and great_expectations connectors 'on the roadmap' and ask users to email in requests - a 20-person team could clear that whole queue by embedding an open-source connector platform instead of building each one. | R28: Etai Mizrahi (CEO) | S28: =COUNTIF(Contacts!$A:$A,A28) -> 1
A29: SigNoz | B29: signoz.io | C29: USA | D29: Dev tools | F29: Observability | G29: Open-source OTel-native observability | H29: Series A $20M Dec 2025 (CB Insights (https://www.cbinsights.com/company/signoz)) | I29: ~51 (CB Insights (https://www.cbinsights.com/company/signoz)) | J29: Discord alert-channel request open since Jan 2023 from a paying-user thread (#2154 (https://github.com/SigNoz/signoz/issues/2154)); 24 open integration issues | K29: 2/2/2/2/0 | L29: 8 | M29: 2 | N29: Ivica | O29: The Discord alert-channel request your own team filed from a paying-user thread has been open since January 2023. | P29: The Discord alert-channel request your own team filed from a user Slack thread has been open since January 2023 - open-source to open-source, ByteChef could give SigNoz every alert destination Datadog has without burning core engineering time. | R29: Pranay Prateek (Co-founder) | S29: =COUNTIF(Contacts!$A:$A,A29) -> 1
A30: Awell | B30: awellhealth.com | C30: Belgium | D30: EU vertical | F30: Health (clinical workflows) | G30: Developer platform for clinical workflows (CareOps) | H30: Seed $5M, Sep 2023 (Tech.eu (https://tech.eu/2023/09/19/awell-secures-5m-to-automate-clinician-workflows/)) | I30: unknown | J30: EHR connectivity hand-built extension by extension (developer hub (https://developers.awellhealth.com/awell-extensions/marketplace/athenahealth)); NOTE: partial conceptual overlap with ByteChef - scope pitch to EHR connector infra | K30: 2/1/2/2/1 | L30: 8 | M30: 2 | N30: Co-founder | O30: Each EHR integration is hand-built extension by extension - a self-serve connector catalog while your team stays on care flows. | P30: Your extensions marketplace shows each EHR integration built by hand - an embeddable integration engine could give Awell customers a self-serve connector catalog while your team stays focused on care flows. | Q30: Conceptual overlap with ByteChef - scope pitch to EHR connector infra | R30: Thomas Vande Casteele (Co-founder & CEO) | S30: =COUNTIF(Contacts!$A:$A,A30) -> 1
A31: Chainels | B31: getchainels.com | C31: Netherlands | D31: EU vertical | F31: Proptech (tenant experience) | G31: Tenant-experience app (400+ communities, 16 countries) | H31: Series A ~€3M, Jan 2023 (EuropaProperty (https://europaproperty.com/chainels-secures-e3-million-series-a-investment/)) | I31: unknown | J31: Syncs lease/billing/maintenance from each landlord's PMS/ERP; modest marketplace (Entrata, Lavanda, Yardi, Dynamics, HubSpot, Stripe) (marketplace (https://getchainels.com/marketplace/urbanos)) | K31: 2/1/2/2/1 | L31: 8 | M31: 2 | N31: Co-founder | O31: Every new landlord runs a PMS your Entrata/Yardi connectors do not cover - stop letting PMS hookups gate deals. | P31: Every new landlord you sign runs a different PMS than your Entrata/Yardi connectors cover - we give vertical SaaS teams an embedded integration layer so the long tail of PMS hookups stops gating deals. | Q31: Headcount unknown | R31: Erwin Buckers (Founder & CEO); Christiaan Titos Bolivar (Lead Developer - no formal CTO title exists) | S31: =COUNTIF(Contacts!$A:$A,A31) -> 2
A32: Dockflow | B32: dockflow.com | C32: Belgium | D32: EU vertical | F32: Logistics (maritime) | G32: Container-tracking platform for freight forwarders | H32: Seed €1.4M Dec 2025 (announcement (https://dockflow.com/29b-in-cargo-tracked-dockflow-raises-e1-4m-to-turn-maritime-data-into-predictive-ai/)) | I32: unknown (small) | J32: Sells on TMS/ERP/WMS hookups; connectors announced one at a time (Portbase) (post (https://dockflow.com/portbase-integration-freight-forwarders/)) | K32: 2/1/2/2/1 | L32: 8 | M32: 2 | N32: Co-founder | O32: Each new forwarder means another TMS/ERP hookup like your Portbase build - let customers self-serve those connections. | P32: Each new forwarder you onboard means another TMS/ERP hookup like your Portbase build - an embedded iPaaS would let your customers self-serve those connections instead of your engineers building each one. | Q32: Headcount unknown | R32: Pauline Van Ostaeyen (Co-Founder - commercial/leadership focus, no one holds literal "CEO" title); Michiel Valee (Co-Founder / Tech Lead) | S32: =COUNTIF(Contacts!$A:$A,A32) -> 2
A33: EverReal | B33: everreal.co | C33: Germany | D33: EU vertical | F33: Proptech (leasing/sales) | G33: White-label rental/sale transaction automation (175k+ units) | H33: Seed 7-figure HTGF 2019; later unknown (HTGF (https://www.htgf.de/en/everreal-successfully-completes-seed-investment-round/)) | I33: unknown | J33: GTM depends on ERP interfaces to housing systems (Wodis, DOMUS, iX-Haus); Aareon connection via third-party low-code tech (Partner-Schnittstellen (https://de.everreal.co/business/partner-schnittstellen)) | K33: 2/1/2/2/1 | L33: 8 | M33: 2 | N33: Co-founder | O33: The Wodis/DOMUS/iX-Haus interface list is the hardest part of every deal - reusable connectors your team configures, not codes. | P33: Your Wodis/DOMUS/iX-Haus interface list is the hardest part of every EverReal deal - an embedded open-source iPaaS turns those one-off ERP projects into reusable connectors your team configures, not codes. | Q33: Later funding rounds unknown | R33: Nessim Djerboua (CEO & Founder); Liviu Ignat (CTO & Co-Founder) | S33: =COUNTIF(Contacts!$A:$A,A33) -> 2
A34: FreightSuite | B34: freightsuite.com | C34: UK | D34: EU vertical | F34: Logistics (forwarding TMS) | G34: AI-native TMS positioned against CargoWise | H34: Pre-A $4.5M, Dec 2025 (The Loadstar (https://theloadstar.com/ls_press_release/freightsuite-secures-4-5m-pre-series-a-to-challenge-the-legacy-tms-market/)) | I34: unknown (small) | J34: Roadmap IS connector buildout: Freightos, Clearport, AEB, CrimsonLogic (Freightos PR (https://www.freightos.com/press-release/freightos-enables-live-air-cargo-booking-in-freightsuites-ai-native-tms/)) | K34: 2/1/2/2/1 | L34: 8 | M34: 2 | N34: Co-founder | O34: Out-integrating CargoWise needs dozens more connectors beyond Freightos and Clearport - a connector factory without diverting your AI roadmap. | P34: To out-integrate CargoWise you'll need dozens more connectors beyond Freightos and Clearport - an embedded open-source iPaaS gives you that connector factory without diverting your core AI roadmap. | Q34: Size unverified | R34: Samuel Moore (Co-Founder (CEO per third-party org chart)); - not confirmed - (William Jacobs is technical co-founder but no source confirms a CTO-equivalent title) | S34: =COUNTIF(Contacts!$A:$A,A34) -> 2
A35: Harbor Lab | B35: harborlab.com | C35: Greece | D35: EU vertical | F35: Logistics (maritime ops) | G35: Port-cost (DA) management for shipowners | H35: Series A €14.7M, May 2024 (EU-Startups (https://www.eu-startups.com/2024/05/greek-maritime-software-harbor-lab-raises-e14-7-million-to-streamline-port-cost-management/)) | I35: ~94–106 (Tracxn (https://tracxn.com/d/companies/harbor-lab/___3YX6sSp1IXiPlUPNMb8HGi0tkxFxqXnC1pFKUb5fC8)) | J35: ERP/accounting hookups required; advertises cloud-ERP integration but no public connector catalog (harborlab.com (https://www.harborlab.com/)) | K35: 2/2/1/2/1 | L35: 8 | M35: 2 | N35: Co-founder | O35: Every DA your platform approves lands in a shipowner's ERP - embedded white-label ERP connectors shipped in weeks. | P35: Every DA your platform approves ultimately lands in a shipowner's ERP - embedded, white-label ERP connectors (SAP, Navision, maritime accounting suites) are exactly what we let SaaS teams ship in weeks. | Q35: Generic pain signal only - verify on first call | R35: Antonis Malaxianakis (Founder & CEO); Spyros Lamprinidis (Chief Technology Officer) | S35: =COUNTIF(Contacts!$A:$A,A35) -> 2
A36: HERO Software | B36: hero-software.de | C36: Germany | D36: EU vertical | F36: Construction (trades) | G36: Cloud software for tradespeople DACH; 30k+ users | H36: Series B €40M, Jul 2024 (Tech.eu (https://tech.eu/2024/07/12/hero-software-secures-40m-series-b-for-tradespeople-saas-platform/)) | I36: 125+ (one source ~230) (about (https://hero-software.de/about-us)) | J36: Interface list bounded, partly export-based: DATEV export, Datanorm/IDS/UGL formats (Schnittstellen (https://hero-software.de/features/schnittstellen)) | K36: 2/1/2/2/1 | L36: 8 | M36: 2 | N36: Co-founder | O36: Your Schnittstellen page covers DATEV export and supplier data formats - each new country means new systems; solve it embedded. | P36: Your Schnittstellen page covers DATEV export and supplier data formats - as the DACH market leader expands across Europe, each new country means new accounting/supplier systems, precisely the connector problem we solve embedded in your product. | Q36: Possibly ~230 employees - verify | R36: Michael Kessler (Founder & CEO (Geschäftsführer)); Constantin Schomburg (Chief Technology Officer) | S36: =COUNTIF(Contacts!$A:$A,A36) -> 2
A37: Legl | B37: legl.com | C37: UK | D37: EU vertical | F37: Legal (law-firm ops) | G37: Payments, onboarding, AML/compliance for law firms | H37: Series B $18M, May 2022 (TechCrunch (https://techcrunch.com/2022/05/17/legl-series-b/)) | I37: unknown | J37: Only a handful of PMS connectors (Clio, Actionstep, Sharedo) vs dozens in market (integrations (https://legl.com/integrations)) | K37: 2/1/2/2/1 | L37: 8 | M37: 2 | N37: Co-founder | O37: Clio, Actionstep and Sharedo are built but most UK firms sit on other PMS - cover the long tail without a connector team. | P37: You've built Clio, Actionstep and Sharedo integrations, but most UK firms sit on other PMS - an embedded integration platform would let you cover the long tail without a connector team. | Q37: Headcount unknown | R37: Julia Salasky (CEO); Matt Jared (CTO) | S37: =COUNTIF(Contacts!$A:$A,A37) -> 2
A38: Rentio | B38: rentio.be | C38: Belgium | D38: EU vertical | F38: Proptech (rental mgmt) | G38: Rental management + payments for Belgian landlords/agencies | H38: Seed €1.3M Baloise 2020 (Baloise (https://www.baloise.com/en/home/news-stories/news/media-releases/2020/baloise-insurance-invests-in-digital-rental-process-of-rentio.html)) | I38: unknown (small) | J38: Accounting via third-party invoicing bridge EenvoudigFactureren rather than native (help doc (https://help.eenvoudigfactureren.be/support/solutions/articles/101000479768-rentio-de-totaaloplossing-voor-ver-huur)) | K38: 2/1/2/2/1 | L38: 8 | M38: 2 | N38: Co-founder | O38: Accounting sync routes through EenvoudigFactureren today - own native Exact/Winbooks/bank connections in-product. | P38: You route accounting sync through EenvoudigFactureren today - an embedded iPaaS would let Rentio own native Exact/Winbooks/bank connections in-product, without an integrations hire. | Q38: Stale seed round; size unknown - confirm company activity | R38: Stijn Roels (CEO (LinkedIn shows "Co-Founder")); - not confirmed - (No source titles anyone CTO; Dries Van Schevensteen is Lead Engineer/Developer) | S38: =COUNTIF(Contacts!$A:$A,A38) -> 2
A39: Carv | B39: carv.com | C39: Netherlands | D39: HR/fin-ops | F39: Recruiting AI | G39: Agentic AI for volume hiring that writes back into the ATS | H39: Seed $10M, Jun 2024 (PR Newswire (https://www.prnewswire.com/news-releases/amsterdam-based-carv-raises-10m-to-offload-admin-from-recruiters-and-realize-recruiter-ai-synergy-302162038.html)) | I39: unknown (seed scale) | J39: Product depends on per-ATS integrations; public list short (Bullhorn, Workable, Recruitee, Carerix, Lexo) vs. hundreds of ATSes (Bullhorn page (https://www.carv.com/integrations/bullhorn), ATS guide (https://www.carv.com/guides/guide-ai-and-the-ats-three-setups-for-seamless-recruitment-process)) | L39: 8 | M39: 2 | N39: Ivica | O39: Carv's value lands only when data flows back into the customer's ATS and you support a handful today - get Bullhorn plus the long tail. | P39: Carv's value lands only when structured data flows back into the customer's ATS, and you support a handful today - an embedded iPaaS gets you Bullhorn-plus-the-long-tail without an integrations backlog blocking sales. | R39: Barend Raaff (Co-Founder - no one holds explicit "CEO" title; prior CEO experience at Harver); Steven Kroon (Chief Technology Officer) | S39: =COUNTIF(Contacts!$A:$A,A39) -> 2
A40: Circula | B40: circula.com | C40: Germany | D40: HR/fin-ops | F40: Expense / spend | G40: Expense management, benefits and cards with deep DATEV focus | H40: Series A €12M (2022) + €15M ext (May 2025) (EU-Startups (https://www.eu-startups.com/2025/05/german-fintech-startup-circula-secures-e15-million-as-it-cuts-expense-admin-by-80/)) | I40: ~100–150 emp (EU-Startups 2022 (https://www.eu-startups.com/2022/01/berlin-based-employee-finance-app-circula-scores-e12-million-and-plans-international-expansion/)) | J40: Integration rated weak spot at 8.2 on G2, reviewers citing "more manual entry and potential errors" (Research.com (https://research.com/software/reviews/circula), G2 (https://www.g2.com/products/circula/reviews)) | L40: 8 | M40: 2 | N40: Ivica | O40: G2 scores integrations as your weakest dimension with manual re-entry complaints - extend DATEV-grade depth to every payroll and HR system. | P40: Circula wins on DATEV depth, but G2 scores integrations as your weakest dimension with reviewers citing manual re-entry - an embedded integration layer would extend that DATEV-grade experience to every payroll and HR system your customers run. | Q40: Weaker pain evidence | R40: Nikolai Skatchkov (CEO & Co-Founder); Roman Leicht (CTO & Co-Founder) | S40: =COUNTIF(Contacts!$A:$A,A40) -> 2
...

Sheet Contacts
A1: company | B1: name | C1: role | D1: title_check | E1: linkedin | F1: confidence | G1: followed_on_linkedin | H1: note_draft | I1: status | J1: notes
A2: Plancraft | B2: Julian Wiedenhaus | C2: CEO & Co-founder | E2: https://www.linkedin.com/in/julianwiedenhaus/ | G2: Y | H2: Hi Julian - noticed Plancraft's DATEV workflow still leans on CSV export/import while you scale across 11 countries. We help construction-tech platforms ship real two-way accounting & supplier APIs fast. Worth a quick chat?
A3: Atlar | B3: Johannes Elgh | C3: CTO & Co-founder | E3: https://www.linkedin.com/in/jelgh/ | G3: Y | H3: Hi Johannes - saw Atlar is staffing a 9-engineer Connectivity team for bank/ERP integrations. Worth comparing notes on what an embedded open-source integration layer could take off that roadmap?
A4: Hyperline | B4: Clément Garbay | C4: Co-founder & CTO | E4: https://www.linkedin.com/in/clementgarbay/ | G4: Y | H4: Hi Clément - your changelog shows accounting connectors shipping one at a time (Zoho Books, then NetSuite/Rillet). We help teams like Hyperline ship ten a quarter without burning core eng. Open to a quick chat?
A5: Payslip | B5: Fidelma McGuirk | C5: Founder & CEO | E5: https://www.linkedin.com/in/fidelmamcguirk/ | G5: Y | H5: Hi Fidelma - noticed Payslip's team hand-builds every HCM-to-payroll connector (Workday PECI, SuccessFactors). We turn that workload into configuration on an embedded platform. Worth a quick chat?
A6: Sequence | B6: Riya Grover | C6: Co-founder & CEO | E6: https://www.linkedin.com/in/riya-grover-a22a4822/ | G6: Y | H6: Hi Riya - Sequence's docs route NetSuite customers to CSV exports and "talk to our team." We help billing platforms make NetSuite (and the next ten ERPs) native. Worth a quick chat?
A7: Zelt | B7: Chris Priebe | C7: Co-founder & CEO | E7: https://www.linkedin.com/in/chrisagain/ | G7: Y | H7: Hi Chris - reviews of Zelt flag the missing integration ecosystem and public API. An embedded iPaaS gives you both, plus fixes for things like the Nest pension sync. Worth a quick chat?
A8: Coperniq | B8: Abdullah Al-Zandani | C8: CEO | E8: https://www.linkedin.com/in/azandani/ | G8: Y | H8: Hi Abdullah - Coperniq's support docs list ~8 native integrations, with the rest routed through Zapier. We help teams ship that long tail natively and white-labeled. Worth a quick chat?
A9: Latchel | B9: Ethan Lieber | C9: CEO & Co-founder | E9: https://www.linkedin.com/in/ethanlieber/ | G9: Y | H9: Hi Ethan - congrats on the Series A. Saw the funds are earmarked to deepen third-party property management integrations - we help compress that roadmap from quarters to weeks. Worth a quick chat?
A10: Lawmatics | B10: Matt Spiegel | C10: Founder & CEO | E10: https://www.linkedin.com/in/mattspiegelesq/ | G10: Y | H10: Hi Matt - G2 reviewers praise Lawmatics' automation but repeatedly flag integrations as a weak spot. We help close that gap without staffing a connector team. Worth a quick chat?
A11: Checkly | B11: Hannes Lenke | C11: CEO | E11: https://www.linkedin.com/in/hanneslenke/ | G11: Y | H11: Hi Hannes - Checkly's alert-channel list is a fraction of Datadog's, and the community has filed integration requests for years. We help you match that catalog breadth at startup cost. Worth a quick chat?
A12: Infisical | B12: Maidul Islam | C12: Co-founder | E12: https://www.linkedin.com/in/maidul98/ | G12: Y | H12: Hi Maidul - secret-sync bugs like the GitLab masked-sync failure have sat open since 2024 across Infisical's hand-built connectors. We maintain 190+ so yours don't rot. Worth a quick chat?
A13: Plane | B13: Vamsi Kurama | C13: CEO & Co-founder | E13: https://www.linkedin.com/in/vamsi-kurama/ | G13: Y | H13: Hi Vamsi - Plane's Gitea-sync issue has 94 upvotes since 2023, with GitLab parity and Mattermost queued behind it. We can power those syncs so your engineers stay on core PM. Worth a chat?
... A16: Awell | B16: Thomas Vande Casteele | C16: Co-founder & CEO | E16: https://www.linkedin.com/in/thomasvdc/ | G16: Y | H16: Hi Thomas - noticed each EHR integration at Awell is hand-built extension by extension. We offer a self-serve connector catalog so your team stays focused on care flows. Worth a quick chat?
A17: Chainels | B17: Erwin Buckers | C17: Founder & CEO | D17: Target: CEO | E17: https://www.linkedin.com/in/erwin-buckers-35699028/ | F17: High
A18: Chainels | B18: Christiaan Titos Bolivar | C18: Lead Developer - no formal CTO title exists | D18: Target: CTO (closest equiv.) | E18: https://www.linkedin.com/in/christiaan-titos-bolivar-b17550ba/ | F18: Medium
A19: Dockflow | B19: Pauline Van Ostaeyen | C19: Co-Founder - commercial/leadership focus, no one holds literal "CEO" title | D19: Target: CEO (closest equiv.) | E19: https://be.linkedin.com/in/paulinevanostaeyen | F19: Low
A20: Dockflow | B20: Michiel Valee | C20: Co-Founder / Tech Lead | D20: Target: CTO (closest equiv.) | E20: https://be.linkedin.com/in/michielvalee | F20: Medium
A21: EverReal | B21: Nessim Djerboua | C21: CEO & Founder | D21: Target: CEO | E21: https://www.linkedin.com/in/nessimdjerboua/ | F21: High
A22: EverReal | B22: Liviu Ignat | C22: CTO & Co-Founder | D22: Target: CTO | E22: https://www.linkedin.com/in/liviu-ignat-76835b21/ | F22: High
A23: FreightSuite | B23: Samuel Moore | C23: Co-Founder (CEO per third-party org chart) | D23: Target: CEO | E23: https://www.linkedin.com/in/samuel-moore-370767206/ | F23: Medium
A24: FreightSuite | B24: - not confirmed - | C24: William Jacobs is technical co-founder but no source confirms a CTO-equivalent title | D24: Target: CTO | E24: https://uk.linkedin.com/in/william-jacobs-4233665b | F24: Low
A25: Harbor Lab | B25: Antonis Malaxianakis | C25: Founder & CEO | D25: Target: CEO | E25: https://gr.linkedin.com/in/antonis-malaxianakis-7b656b6b | F25: High
A26: Harbor Lab | B26: Spyros Lamprinidis | C26: Chief Technology Officer | D26: Target: CTO | E26: https://www.linkedin.com/in/spyroslambrinidis/ | F26: Medium
A27: HERO Software | B27: Michael Kessler | C27: Founder & CEO (Geschäftsführer) | D27: Target: CEO | E27: https://de.linkedin.com/in/michael-kessler-6201b7a0 | F27: High
A28: HERO Software | B28: Constantin Schomburg | C28: Chief Technology Officer | D28: Target: CTO | E28: https://www.linkedin.com/in/cschomburg/ | F28: High
... A46: Solvimon | B46: Etienne Gerts | C46: Co-Founder & CTO | D46: Target: CTO | E46: https://www.linkedin.com/in/etienne-gerts-91636b4/ | F46: High
A47: Younium | B47: Niclas Lilja | C47: Founder & CEO | E47: https://www.linkedin.com/in/niclas-lilja/ | H47: Hi Niclas - saw a G2 review calling out your Salesforce integration. We help subscription platforms rebuild CRM/ERP sync once and expose every connector mid-market buyers expect. Worth a quick chat?
A48: AgVend | B48: Alexander Reichert | C48: Co-Founder & CEO | E48: https://www.linkedin.com/in/alexanderreichert | H48: Hi Alexander - your grower portals live or die by ERP, agronomy and grain-system syncs. We help teams onboard the next ag ERP without a bespoke build. Open to a quick chat?
A49: AgVend | B49: Eli Rosenberg | C49: Co-Founder & CPO | H49: Hi Eli - following up on integration coverage for AgVend's grower portals (ERP/agronomy/grain-system syncs) - happy to share how we help teams ship these without bespoke builds.
A50: Archy | B50: Jonathan Rat | C50: Co-Founder & CEO | E50: https://www.linkedin.com/in/jonathanrat | H50: Hi Jonathan - sensors, imaging AI and payer systems each need a bespoke connector today. We help teams ship these natively instead of one TWAIN driver at a time. Worth a chat?
A51: Carepatron | B51: Jamie Frew | C51: Co-Founder | E51: https://www.linkedin.com/in/jamie-frew-b843618 | H51: Hi Jamie - Capterra reviewers keep asking Carepatron for Medicare, insurance-billing and accounting integrations. We help teams ship these as embedded, white-label connectors. Open to connecting?
A52: Hona | B52: Matt McClellan | C52: Co-Founder | E52: https://www.linkedin.com/in/matthew-mcclellan22 | H52: Hi Matt - Hona's edge is deep case-management sync with Clio, Filevine and Smokeball. We help teams cover the next ten PMSs prospects ask about, fast. Worth a quick chat?
A53: Hona | B53: Joshua Christensen | C53: Co-Founder & CTO | E53: https://www.linkedin.com/in/joshua-n-christensen | H53: Hi Joshua - curious how the team is scaling PMS integrations beyond Clio/Filevine/Smokeball. We help teams like Hona's ship the long tail of case-management syncs without the bespoke build each time.
A54: Milk Moovement | B54: Jon King | C54: Co-Founder & CEO | E54: https://www.linkedin.com/in/jonathanjking | H54: Hi Jon - saw Milk Moovement ingests lab results via API, FTP or email. We help teams turn that legacy glue into productized, white-label integrations co-ops configure themselves. Worth a chat?
A55: Milk Moovement | B55: Christopher O'Malley | C55: CTO | E55: https://www.linkedin.com/in/comalley | H55: Hi Christopher - curious how the team is productizing lab-result ingestion (API/FTP/email) today. We help teams turn that into self-serve, white-label integrations for co-ops. Open to connecting?
A56: RentCheck | B56: Marco Nelson | C56: Founder & CEO | E56: https://www.linkedin.com/in/marco-nelson-67470530 | H56: Hi Marco - noticed Buildium is still "coming soon" on RentCheck's integrations page. We help teams ship Buildium, Propertyware and the PM long tail in weeks, not quarters. Worth a chat?
A57: RentCheck | B57: Matias Pan | C57: Head of Engineering | E57: https://www.linkedin.com/in/matias-pan-41729a279 | H57: Hi Matias - curious about the roadmap for Buildium/Propertyware and the rest of the PM integration long tail at RentCheck. We help teams ship these in weeks. Open to connecting?
A58: Siteline | B58: Claire Wilson | C58: Co-Founder & CEO | E58: https://www.linkedin.com/in/construction-claire | H58: Hi Claire - saw Siteline maintains 8+ bidirectional construction ERP syncs in-house. We help teams offload that connector maintenance so engineers stay on billing workflows. Worth a chat?
A59: Siteline | B59: Gloria Lin | C59: Co-Founder & CPO | E59: https://www.linkedin.com/in/glo | H59: Hi Gloria - curious how the team is prioritizing the 8+ construction ERP syncs Siteline maintains in-house. We help offload that maintenance so engineering stays on core billing workflows.
...

Sheet Notes
A1: HOW TO USE THIS WORKBOOK
A2: Targets: one row per company (101). Research columns came from the July target list (+ Croatia segment, Oct 4). Yellow columns are yours to fill in as outreach runs. Row 2 is the example row from the old tracker.
A3: Contacts: one row per person, joined to Targets by company name. n_contacts on Targets counts them. followed_on_linkedin = Y for the 15 contacts listed under "Followed from 15" in the old tracker.
A4: first_line = the shorter hook from the tracker. research_hook = the original hook from the research doc. Re-verify the underlying fact before sending either.
A5: Below: methodology, caveats, wave plans, low-confidence lists and exclusions from bytechef-embedded-target-list-2026-07.md (tables moved into the other tabs).
A7: ByteChef Embedded - Outbound Target List (first cut)
A9: Date: July 28, 2026 (Croatia segment added October 4, 2026) · Companies: 101 across 5 segments · Purpose: GTM strategy §7.3 - the 90-day embedded validation sprint's outreach list.
A11: How this list was built
A13: Four parallel research passes (EU vertical SaaS · US/RoW vertical SaaS · dev tools & horizontal B2B · HR/fin-ops/accounting) against the §7.3 criteria: B2B SaaS, seed–Series B, ~10–200 employees, demonstrated integration pain, verticals whose customers demand integrations. Competitors (iPaaS / unified-API / workflow-automation vendors) and Series C+ / >300-employee companies were excluded.
A15: Scoring rubric (per company, /10): Stage fit 0–2 · Size fit 0–2 · Pain evidence 0–3 · Vertical fit 0–2 · EU bonus +1 (applied to European HQs incl. UK - deduct 1 for strict EU-27).
A17: Global caveats - read before sending anything:
A18: 1. Most companies' /integrations pages blocked automated fetching (403). "Thin page" judgments rest on review sites, support docs, changelogs, and search-indexed copy. Verify each company's current integrations page manually before citing it in an email.
... A157: - No qualifying candidates found in Croatian legal, education or energy SaaS.
